Workbook

Sheet 経営比較
A1: Guard・Send・セット 経営比較
A2: 選択条件は4行に表示。共通率は前提と出典E4〜E6。価格・配分は正式決定ではない。
A4: 選択Guard案 | B4: =INDEX('前提と出典'!A41:A43,'前提と出典'!$B$15+1) -> C Guard | D4: 選択Send案 | E4: =INDEX('前提と出典'!A46:A48,'前提と出典'!$B$16+1) -> D | G4: 割引 | H4: ='前提と出典'!$B$17 -> 1000
A6: 共通配分率 | B6: 初回黒字企業数 | C6: 継続黒字企業数 | D6: 両サービス継続黒字 | E6: 100社差引 | F6: 100社Guard差引 | G6: 100社Send差引
A7: ='前提と出典'!E4 -> 0.3 | B7: =IF(MIN('利益曲線'!AA5:AA1004)>1000,"範囲内なし",MIN('利益曲線'!AA5:AA1004)) -> 21 | C7: =IF(MAX('利益曲線'!AB5:AB1004)>=1000,"範囲内なし",MAX(1,MAX('利益曲線'!AB5:AB1004)+1)) -> 21 | D7: =IF(MAX('利益曲線'!AC5:AC1004)>=1000,"範囲内なし",MAX(1,MAX('利益曲線'!AC5:AC1004)+1)) -> 49 | E7: =INDEX('利益曲線'!T5:T1004,100) -> 229611.39 | F7: =INDEX('利益曲線'!R5:R1004,100) -> 193157.4 | G7: =INDEX('利益曲線'!S5:S1004,100) -> 36453.988
A8: ='前提と出典'!E5 -> 0.4 | B8: =IF(MIN('利益曲線'!AD5:AD1004)>1000,"範囲内なし",MIN('利益曲線'!AD5:AD1004)) -> 22 | C8: =IF(MAX('利益曲線'!AE5:AE1004)>=1000,"範囲内なし",MAX(1,MAX('利益曲線'!AE5:AE1004)+1)) -> 22 | D8: =IF(MAX('利益曲線'!AF5:AF1004)>=1000,"範囲内なし",MAX(1,MAX('利益曲線'!AF5:AF1004)+1)) -> 55 | E8: =INDEX('利益曲線'!W5:W1004,100) -> 197167.99 | F8: =INDEX('利益曲線'!U5:U1004,100) -> 168018.67 | G8: =INDEX('利益曲線'!V5:V1004,100) -> 29149.315
A9: ='前提と出典'!E6 -> 0.5 | B9: =IF(MIN('利益曲線'!AG5:AG1004)>1000,"範囲内なし",MIN('利益曲線'!AG5:AG1004)) -> 25 | C9: =IF(MAX('利益曲線'!AH5:AH1004)>=1000,"範囲内なし",MAX(1,MAX('利益曲線'!AH5:AH1004)+1)) -> 25 | D9: =IF(MAX('利益曲線'!AI5:AI1004)>=1000,"範囲内なし",MAX(1,MAX('利益曲線'!AI5:AI1004)+1)) -> 62 | E9: =INDEX('利益曲線'!Z5:Z1004,100) -> 164724.59 | F9: =INDEX('利益曲線'!X5:X1004,100) -> 142879.94 | G9: =INDEX('利益曲線'!Y5:Y1004,100) -> 21844.643
A12: 企業数 | B12: 総売上 | C12: 基本料金net | D12: 従量売上 | E12: 率2配分 | F12: DNS仕入 | G12: G+S infra運用 | H12: 決済手数料 | I12: 率2後差引
A13: 10 | B13: =INDEX('利益曲線'!E5:E1004,A13)+INDEX('利益曲線'!F5:F1004,A13)+INDEX('利益曲線'!G5:G1004,A13)+INDEX('利益曲線'!H5:H1004,A13) -> 59256.472 | C13: =INDEX('利益曲線'!E5:E1004,A13)+INDEX('利益曲線'!F5:F1004,A13) -> 32443.401 | D13: =INDEX('利益曲線'!G5:G1004,A13)+INDEX('利益曲線'!H5:H1004,A13) -> 26813.071 | E13: =C13*'前提と出典'!E5 -> 12977.361 | F13: =INDEX('利益曲線'!O5:O1004,A13) -> 22500 | G13: =INDEX('利益曲線'!I5:I1004,A13)+INDEX('利益曲線'!J5:J1004,A13)+INDEX('利益曲線'!K5:K1004,A13)+INDEX('利益曲線'!L5:L1004,A13)+INDEX('利益曲線'!M5:M1004,A13)+INDEX('利益曲線'!N5:N1004,A13) -> 49059.089 | H13: =B13*'前提と出典'!$B$7 -> 2133.233 | I13: =INDEX('利益曲線'!W5:W1004,A13) -> -27413.21
A14: 30 | B14: =INDEX('利益曲線'!E5:E1004,A14)+INDEX('利益曲線'!F5:F1004,A14)+INDEX('利益曲線'!G5:G1004,A14)+INDEX('利益曲線'!H5:H1004,A14) -> 177769.42 | C14: =INDEX('利益曲線'!E5:E1004,A14)+INDEX('利益曲線'!F5:F1004,A14) -> 97330.204 | D14: =INDEX('利益曲線'!G5:G1004,A14)+INDEX('利益曲線'!H5:H1004,A14) -> 80439.213 | E14: =C14*'前提と出典'!E5 -> 38932.082 | F14: =INDEX('利益曲線'!O5:O1004,A14) -> 29789.497 | G14: =INDEX('利益曲線'!I5:I1004,A14)+INDEX('利益曲線'!J5:J1004,A14)+INDEX('利益曲線'!K5:K1004,A14)+INDEX('利益曲線'!L5:L1004,A14)+INDEX('利益曲線'!M5:M1004,A14)+INDEX('利益曲線'!N5:N1004,A14) -> 81655.397 | H14: =B14*'前提と出典'!$B$7 -> 6399.699 | I14: =INDEX('利益曲線'!W5:W1004,A14) -> 20992.742
A15: 50 | B15: =INDEX('利益曲線'!E5:E1004,A15)+INDEX('利益曲線'!F5:F1004,A15)+INDEX('利益曲線'!G5:G1004,A15)+INDEX('利益曲線'!H5:H1004,A15) -> 296282.36 | C15: =INDEX('利益曲線'!E5:E1004,A15)+INDEX('利益曲線'!F5:F1004,A15) -> 162217.01 | D15: =INDEX('利益曲線'!G5:G1004,A15)+INDEX('利益曲線'!H5:H1004,A15) -> 134065.35 | E15: =C15*'前提と出典'!E5 -> 64886.803 | F15: =INDEX('利益曲線'!O5:O1004,A15) -> 49649.162 | G15: =INDEX('利益曲線'!I5:I1004,A15)+INDEX('利益曲線'!J5:J1004,A15)+INDEX('利益曲線'!K5:K1004,A15)+INDEX('利益曲線'!L5:L1004,A15)+INDEX('利益曲線'!M5:M1004,A15)+INDEX('利益曲線'!N5:N1004,A15) -> 99751.706 | H15: =B15*'前提と出典'!$B$7 -> 10666.165 | I15: =INDEX('利益曲線'!W5:W1004,A15) -> 71328.526
A16: 100 | B16: =INDEX('利益曲線'!E5:E1004,A16)+INDEX('利益曲線'!F5:F1004,A16)+INDEX('利益曲線'!G5:G1004,A16)+INDEX('利益曲線'!H5:H1004,A16) -> 592564.72 | C16: =INDEX('利益曲線'!E5:E1004,A16)+INDEX('利益曲線'!F5:F1004,A16) -> 324434.01 | D16: =INDEX('利益曲線'!G5:G1004,A16)+INDEX('利益曲線'!H5:H1004,A16) -> 268130.71 | E16: =C16*'前提と出典'!E5 -> 129773.61 | F16: =INDEX('利益曲線'!O5:O1004,A16) -> 99298.324 | G16: =INDEX('利益曲線'!I5:I1004,A16)+INDEX('利益曲線'!J5:J1004,A16)+INDEX('利益曲線'!K5:K1004,A16)+INDEX('利益曲線'!L5:L1004,A16)+INDEX('利益曲線'!M5:M1004,A16)+INDEX('利益曲線'!N5:N1004,A16) -> 144992.48 | H16: =B16*'前提と出典'!$B$7 -> 21332.33 | I16: =INDEX('利益曲線'!W5:W1004,A16) -> 197167.99
A17: 300 | B17: =INDEX('利益曲線'!E5:E1004,A17)+INDEX('利益曲線'!F5:F1004,A17)+INDEX('利益曲線'!G5:G1004,A17)+INDEX('利益曲線'!H5:H1004,A17) -> 1777694.2 | C17: =INDEX('利益曲線'!E5:E1004,A17)+INDEX('利益曲線'!F5:F1004,A17) -> 973302.04 | D17: =INDEX('利益曲線'!G5:G1004,A17)+INDEX('利益曲線'!H5:H1004,A17) -> 804392.13 | E17: =C17*'前提と出典'!E5 -> 389320.82 | F17: =INDEX('利益曲線'!O5:O1004,A17) -> 297894.97 | G17: =INDEX('利益曲線'!I5:I1004,A17)+INDEX('利益曲線'!J5:J1004,A17)+INDEX('利益曲線'!K5:K1004,A17)+INDEX('利益曲線'!L5:L1004,A17)+INDEX('利益曲線'!M5:M1004,A17)+INDEX('利益曲線'!N5:N1004,A17) -> 367955.56 | H17: =B17*'前提と出典'!$B$7 -> 63996.99 | I17: =INDEX('利益曲線'!W5:W1004,A17) -> 658525.83
A18: 1000 | B18: =INDEX('利益曲線'!E5:E1004,A18)+INDEX('利益曲線'!F5:F1004,A18)+INDEX('利益曲線'!G5:G1004,A18)+INDEX('利益曲線'!H5:H1004,A18) -> 5925647.2 | C18: =INDEX('利益曲線'!E5:E1004,A18)+INDEX('利益曲線'!F5:F1004,A18) -> 3244340.1 | D18: =INDEX('利益曲線'!G5:G1004,A18)+INDEX('利益曲線'!H5:H1004,A18) -> 2681307.1 | E18: =C18*'前提と出典'!E5 -> 1297736.1 | F18: =INDEX('利益曲線'!O5:O1004,A18) -> 992983.24 | G18: =INDEX('利益曲線'!I5:I1004,A18)+INDEX('利益曲線'!J5:J1004,A18)+INDEX('利益曲線'!K5:K1004,A18)+INDEX('利益曲線'!L5:L1004,A18)+INDEX('利益曲線'!M5:M1004,A18)+INDEX('利益曲線'!N5:N1004,A18) -> 1071326.4 | H18: =B18*'前提と出典'!$B$7 -> 213323.3 | I18: =INDEX('利益曲線'!W5:W1004,A18) -> 2350278.3
A21: 共通率 | B21: 単月黒字月 | C21: 累積回収月 | D21: 最大累積赤字 | E21: 36月累積差引
A22: ='前提と出典'!E4 -> 0.3 | B22: =IF(MIN('累積回収'!AH5:AH40)>36,"36月内なし",MIN('累積回収'!AH5:AH40)) -> 7 | C22: =IF(MIN('累積回収'!AI5:AI40)>36,"36月内なし",MIN('累積回収'!AI5:AI40)) -> 13 | D22: =MAX('累積回収'!AE5:AE40) -> 158010.6 | E22: ='累積回収'!AB40 -> 3702781
A23: ='前提と出典'!E5 -> 0.4 | B23: =IF(MIN('累積回収'!AJ5:AJ40)>36,"36月内なし",MIN('累積回収'!AJ5:AJ40)) -> 8 | C23: =IF(MIN('累積回収'!AK5:AK40)>36,"36月内なし",MIN('累積回収'!AK5:AK40)) -> 14 | D23: =MAX('累積回収'!AF5:AF40) -> 181755.66 | E23: ='累積回収'!AC40 -> 3054561.8
A24: ='前提と出典'!E6 -> 0.5 | B24: =IF(MIN('累積回収'!AL5:AL40)>36,"36月内なし",MIN('累積回収'!AL5:AL40)) -> 9 | C24: =IF(MIN('累積回収'!AM5:AM40)>36,"36月内なし",MIN('累積回収'!AM5:AM40)) -> 16 | D24: =MAX('累積回収'!AG5:AG40) -> 210902.52 | E24: ='累積回収'!AD40 -> 2406342.6
A27: 初期費用 | B27: =IF('前提と出典'!$B$32="","未入力・未算入",'前提と出典'!$B$32) -> 未入力・未算入
A28: 導入率からの対象企業数 | B28: ='前提と出典'!$B$28*'前提と出典'!$B$29 -> 100
A29: 参照Guard/Send/Set対象率 | B29: ='契約別単価'!B5 -> 0.895 | C29: ='契約別単価'!B6 -> 0.995 | D29: ='契約別単価'!B7 -> 0.895
A31: 各価格・比率・為替・利用・割引は前提と出典で変更。契約形態だけの評価はB34で1/2/3を選択。
A32: セット合計黒字とGuard/Send独立黒字を分ける。51送信者以上・101PC以上は要見積。
A33: 同一企業の規模仮説はPR14のPC帯を再利用。前回の全国従業者ベンチマークによるSend分布と別の感度。
A35: 共通率 | B35: 導入目標社数時の差引 | C35: 導入目標時DNS原価
A36: ='前提と出典'!E4 -> 0.3 | B36: =IF(OR(B28<1,B28>1000),"評価範囲外",INDEX('利益曲線'!T5:T1004,ROUNDUP(B28,0))) -> 229611.39 | C36: =IF(OR(B28<1,B28>1000),"評価範囲外",INDEX('利益曲線'!O5:O1004,ROUNDUP(B28,0))) -> 99298.324
A37: ='前提と出典'!E5 -> 0.4 | B37: =IF(OR(B28<1,B28>1000),"評価範囲外",INDEX('利益曲線'!W5:W1004,ROUNDUP(B28,0))) -> 197167.99 | C37: =IF(OR(B28<1,B28>1000),"評価範囲外",INDEX('利益曲線'!O5:O1004,ROUNDUP(B28,0))) -> 99298.324
A38: ='前提と出典'!E6 -> 0.5 | B38: =IF(OR(B28<1,B28>1000),"評価範囲外",INDEX('利益曲線'!Z5:Z1004,ROUNDUP(B28,0))) -> 164724.59 | C38: =IF(OR(B28<1,B28>1000),"評価範囲外",INDEX('利益曲線'!O5:O1004,ROUNDUP(B28,0))) -> 99298.324
A40: 導入目標と対象社数の整合 | B40: =IF(AND(B28*('前提と出典'!C36+'前提と出典'!C38)<='前提と出典'!B28*'契約別単価'!B5,B28*('前提と出典'!C37+'前提と出典'!C38)<='前提と出典'!B28*'契約別単価'!B6,B28*'前提と出典'!C38<='前提と出典'!B28*'契約別単価'!B7),"仮定内","構成比を再設定") -> 仮定内
A42: C案：今回指定料金を優先。固定条件比較は今回144ケース。30%は参考、40%と50%を比較。

Sheet 前提と出典
A1: Secure Services 共通料金・原価の設定
A2: 青字は仮定・選択。実請求・公表・仮定を区分。料金・配分は正式決定ではない。
A4: 為替 JPY/USD | B4: 150 | D4: シェア率比較 | E4: 0.3
A5: DNS単価 USD/台 | B5: 0.92 | D5: シェア率比較 | E5: 0.4
A6: MSP最低 USD/月 | B6: 150 | D6: シェア率比較 | E6: 0.5
A7: 決済手数料率 | B7: 0.036
A8: 運用時給 | B8: 4000
A9: Guard support分/社 | B9: 8
A10: Guard support分/PC | B10: 0.1 | D10: 低位送信職務倍率 | E10: 0.5
A11: Guard変動JPY/社 | B11: 50 | D11: 基準送信職務倍率 | E11: 1
A12: Guard変動JPY/PC | B12: 1 | D12: 高位送信職務倍率 | E12: 1.5
A13: Send送信者JPY/名 | B13: 200
A14: 同一企業シナリオ0低1基2高 | B14: 1
A15: Guard案0現行1二段2三段 | B15: 1
A16: Send案0A1C2D | B16: 2
A17: セット基本割引 | B17: 1000
A18: Send利用0低1標2高3上限 | B18: 1
A19: 割引按分0比例1Guard負担 | B19: 0
A20: MSP原価0最低内包1加算 | B20: 0
A21: 現場中心企業の仮比率 | B21: 0.7
A22: 現場型の従業者倍率 | B22: 1.5
A23: 事務型の従業者倍率 | B23: 0.75
A24: 現場型の送信者職務率 | B24: 0.1
... A31: 月間解約率 | B31: 0
A32: 初期投資JPY・未入力除外
A33: Guard従量0一律1累進 | B33: 1
A34: 契約構成0下記1G2S3セット | B34: 0
A35: 契約構成 | B35: 入力比率 | C35: 正規化・有効比率
A36: Guardのみ | B36: 0.4 | C36: =IF($B$34=0,B36/SUM($B$36:$B$38),IF($B$34=1,1,0)) -> 0.4
A37: Sendのみ | B37: 0.3 | C37: =IF($B$34=0,B37/SUM($B$36:$B$38),IF($B$34=2,1,0)) -> 0.3
A38: セット | B38: 0.3 | C38: =IF($B$34=0,B38/SUM($B$36:$B$38),IF($B$34=3,1,0)) -> 0.3
A40: Guard基本案 | B40: 上限1 | C40: 料金1 | D40: 上限2 | E40: 料金2 | F40: 上限3 | G40: 料金3
A41: G0基本5000比較 | B41: 100 | C41: 5000 | D41: 100 | E41: 5000 | F41: 100 | G41: 5000
A42: C Guard | B42: 10 | C42: 3500 | D42: 100 | E42: 5000 | F42: 100 | G42: 5000
A43: G3三段階 | B43: 5 | C43: 2000 | D43: 20 | E43: 3000 | F43: 100 | G43: 4500
A45: Send基本案 | B45: 上限1 | C45: 料金1 | D45: 上限2 | E45: 料金2 | F45: 上限3 | G45: 料金3 | H45: 上限4 | I45: 料金4
A46: A | B46: 10 | C46: 1500 | D46: 50 | E46: 3000 | F46: 50 | G46: 3000 | H46: 50 | I46: 3000
A47: C | B47: 5 | C47: 1000 | D47: 10 | E47: 1500 | F47: 30 | G47: 2500 | H47: 50 | I47: 4000
A48: D | B48: 10 | C48: 1200 | D48: 50 | E48: 2500 | F48: 50 | G48: 2500 | H48: 50 | I48: 2500
A51: Windows PC代表 | B51: 従業者規模アンカー | C51: 低位重み | D51: 基準重み | E51: 高位重み
...

Sheet 同一企業モデル
A1: 同一企業の従業者・PC・送信者（相関仮定）
A2: 同じPC帯・企業規模・職務型から送信者を作る。独立平均の掛算はしない。0PCでもSendは利用可能。
A4: シナリオ | B4: PC帯番号 | C4: 企業型 | D4: 重み | E4: 従業者 | F4: Windows PC | G4: 有料送信者 | H4: G料金対象 | I4: S料金対象 | J4: セット対象 | K4: 選択重み | L4: G基本 | M4: G従量 | N4: S基本 | O4: S従量 | P4: セット割引 | Q4: G割引按分 | R4: S割引按分 | S4: G変動infra | T4: Gsupport | U4: S変動infra | V4: Ssupport | W4: セットG基本 | X4: セットS基本
A5: 0 | B5: 0 | C5: 0 | D5: ='前提と出典'!C52*'前提と出典'!$B$21 -> 0.14 | E5: =ROUNDUP('前提と出典'!B52*'前提と出典'!$B$22,0) -> 6 | F5: ='前提と出典'!A52 -> 0 | G5: =MAX(1,ROUNDUP(E5*'前提と出典'!$B$24*'前提と出典'!E10,0)) -> 1 | H5: =IF(AND(F5>=1,F5<=100),1,0) -> 0 | I5: =IF(G5<=50,1,0) -> 1 | J5: =H5*I5 -> 0 | K5: =IF(A5='前提と出典'!$B$14,D5,0) -> 0 | L5: =IF(H5=0,0,IF(F5<=INDEX('前提と出典'!B41:B43,'前提と出典'!$B$15+1),INDEX('前提と出典'!C41:C43,'前提と出典'!$B$15+1),IF(F5<=INDEX('前提と出典'!D41:D43,'前提と出典'!$B$15+1),INDEX('前提と出典'!E41:E43,'前提と出典'!$B$15+1),INDEX('前提と出典'!G41:G43,'前提と出典'!$B$15+1)))) -> 0 | M5: =IF(H5=0,0,IF('前提と出典'!$B$33=1,MIN(F5,10)*300+MIN(MAX(0,F5-10),20)*250+MAX(0,F5-30)*200,F5*300)) -> 0 | N5: =IF(I5=0,0,IF(G5<=INDEX('前提と出典'!B46:B48,'前提と出典'!$B$16+1),INDEX('前提と出典'!C46:C48,'前提と出典'!$B$16+1),IF(G5<=INDEX('前提と出典'!D46:D48,'前提と出典'!$B$16+1),INDEX('前提と出典'!E46:E48,'前提と出典'!$B$16+1),IF(G5<=INDEX('前提と出典'!F46:F48,'前提と出典'!$B$16+1),INDEX('前提と出典'!G46:G48,'前提と出典'!$B$16+1),INDEX('前提と出典'!I46:I48,'前提と出典'!$B$16+1))))) -> 1200 | O5: =IF(I5=1,G5*'前提と出典'!$B$13,0) -> 200 | P5: =IF(J5=1,MIN('前提と出典'!$B$17,L5+N5),0) -> 0 | Q5: =IF(J5=0,0,IF('前提と出典'!$B$19=0,P5*L5/(L5+N5),MIN(P5,L5))) -> 0 | R5: =P5-Q5 -> 0 | S5: =IF(H5=1,'前提と出典'!$B$11+F5*'前提と出典'!$B$12,0) -> 0 | T5: =IF(H5=1,('前提と出典'!$B$9+F5*'前提と出典'!$B$10)/60*'前提と出典'!$B$8,0) -> 0 | U5: =IF(I5=1,INDEX('前提と出典'!B80:B83,'前提と出典'!$B$18+1)+G5*INDEX('前提と出典'!C80:C83,'前提と出典'!$B$18+1),0) -> 69.771024 | V5: =IF(I5=1,INDEX('前提と出典'!D80:D83,'前提と出典'!$B$18+1)+G5*INDEX('前提と出典'!E80:E83,'前提と出典'!$B$18+1),0) -> 540 | W5: =L5-Q5 -> 0 | X5: =N5-R5 -> 1200
A6: 0 | B6: 0 | C6: 1 | D6: ='前提と出典'!C52*(1-'前提と出典'!$B$21) -> 0.06 | E6: =ROUNDUP('前提と出典'!B52*'前提と出典'!$B$23,0) -> 3 | F6: ='前提と出典'!A52 -> 0 | G6: =MAX(1,ROUNDUP(E6*'前提と出典'!$B$25*'前提と出典'!E10,0)) -> 1 | H6: =IF(AND(F6>=1,F6<=100),1,0) -> 0 | I6: =IF(G6<=50,1,0) -> 1 | J6: =H6*I6 -> 0 | K6: =IF(A6='前提と出典'!$B$14,D6,0) -> 0 | L6: =IF(H6=0,0,IF(F6<=INDEX('前提と出典'!B41:B43,'前提と出典'!$B$15+1),INDEX('前提と出典'!C41:C43,'前提と出典'!$B$15+1),IF(F6<=INDEX('前提と出典'!D41:D43,'前提と出典'!$B$15+1),INDEX('前提と出典'!E41:E43,'前提と出典'!$B$15+1),INDEX('前提と出典'!G41:G43,'前提と出典'!$B$15+1)))) -> 0 | M6: =IF(H6=0,0,IF('前提と出典'!$B$33=1,MIN(F6,10)*300+MIN(MAX(0,F6-10),20)*250+MAX(0,F6-30)*200,F6*300)) -> 0 | N6: =IF(I6=0,0,IF(G6<=INDEX('前提と出典'!B46:B48,'前提と出典'!$B$16+1),INDEX('前提と出典'!C46:C48,'前提と出典'!$B$16+1),IF(G6<=INDEX('前提と出典'!D46:D48,'前提と出典'!$B$16+1),INDEX('前提と出典'!E46:E48,'前提と出典'!$B$16+1),IF(G6<=INDEX('前提と出典'!F46:F48,'前提と出典'!$B$16+1),INDEX('前提と出典'!G46:G48,'前提と出典'!$B$16+1),INDEX('前提と出典'!I46:I48,'前提と出典'!$B$16+1))))) -> 1200 | O6: =IF(I6=1,G6*'前提と出典'!$B$13,0) -> 200 | P6: =IF(J6=1,MIN('前提と出典'!$B$17,L6+N6),0) -> 0 | Q6: =IF(J6=0,0,IF('前提と出典'!$B$19=0,P6*L6/(L6+N6),MIN(P6,L6))) -> 0 | R6: =P6-Q6 -> 0 | S6: =IF(H6=1,'前提と出典'!$B$11+F6*'前提と出典'!$B$12,0) -> 0 | T6: =IF(H6=1,('前提と出典'!$B$9+F6*'前提と出典'!$B$10)/60*'前提と出典'!$B$8,0) -> 0 | U6: =IF(I6=1,INDEX('前提と出典'!B80:B83,'前提と出典'!$B$18+1)+G6*INDEX('前提と出典'!C80:C83,'前提と出典'!$B$18+1),0) -> 69.771024 | V6: =IF(I6=1,INDEX('前提と出典'!D80:D83,'前提と出典'!$B$18+1)+G6*INDEX('前提と出典'!E80:E83,'前提と出典'!$B$18+1),0) -> 540 | W6: =L6-Q6 -> 0 | X6: =N6-R6 -> 1200
A7: 0 | B7: 1 | C7: 0 | D7: ='前提と出典'!C53*'前提と出典'!$B$21 -> 0.315 | E7: =ROUNDUP('前提と出典'!B53*'前提と出典'!$B$22,0) -> 15 | F7: ='前提と出典'!A53 -> 3 | G7: =MAX(1,ROUNDUP(E7*'前提と出典'!$B$24*'前提と出典'!E10,0)) -> 1 | H7: =IF(AND(F7>=1,F7<=100),1,0) -> 1 | I7: =IF(G7<=50,1,0) -> 1 | J7: =H7*I7 -> 1 | K7: =IF(A7='前提と出典'!$B$14,D7,0) -> 0 | L7: =IF(H7=0,0,IF(F7<=INDEX('前提と出典'!B41:B43,'前提と出典'!$B$15+1),INDEX('前提と出典'!C41:C43,'前提と出典'!$B$15+1),IF(F7<=INDEX('前提と出典'!D41:D43,'前提と出典'!$B$15+1),INDEX('前提と出典'!E41:E43,'前提と出典'!$B$15+1),INDEX('前提と出典'!G41:G43,'前提と出典'!$B$15+1)))) -> 3500 | M7: =IF(H7=0,0,IF('前提と出典'!$B$33=1,MIN(F7,10)*300+MIN(MAX(0,F7-10),20)*250+MAX(0,F7-30)*200,F7*300)) -> 900 | N7: =IF(I7=0,0,IF(G7<=INDEX('前提と出典'!B46:B48,'前提と出典'!$B$16+1),INDEX('前提と出典'!C46:C48,'前提と出典'!$B$16+1),IF(G7<=INDEX('前提と出典'!D46:D48,'前提と出典'!$B$16+1),INDEX('前提と出典'!E46:E48,'前提と出典'!$B$16+1),IF(G7<=INDEX('前提と出典'!F46:F48,'前提と出典'!$B$16+1),INDEX('前提と出典'!G46:G48,'前提と出典'!$B$16+1),INDEX('前提と出典'!I46:I48,'前提と出典'!$B$16+1))))) -> 1200 | O7: =IF(I7=1,G7*'前提と出典'!$B$13,0) -> 200 | P7: =IF(J7=1,MIN('前提と出典'!$B$17,L7+N7),0) -> 1000 | Q7: =IF(J7=0,0,IF('前提と出典'!$B$19=0,P7*L7/(L7+N7),MIN(P7,L7))) -> 744.68085 | R7: =P7-Q7 -> 255.31915 | S7: =IF(H7=1,'前提と出典'!$B$11+F7*'前提と出典'!$B$12,0) -> 53 | T7: =IF(H7=1,('前提と出典'!$B$9+F7*'前提と出典'!$B$10)/60*'前提と出典'!$B$8,0) -> 553.33333 | U7: =IF(I7=1,INDEX('前提と出典'!B80:B83,'前提と出典'!$B$18+1)+G7*INDEX('前提と出典'!C80:C83,'前提と出典'!$B$18+1),0) -> 69.771024 | V7: =IF(I7=1,INDEX('前提と出典'!D80:D83,'前提と出典'!$B$18+1)+G7*INDEX('前提と出典'!E80:E83,'前提と出典'!$B$18+1),0) -> 540 | W7: =L7-Q7 -> 2755.3191 | X7: =N7-R7 -> 944.68085
A8: 0 | B8: 1 | C8: 1 | D8: ='前提と出典'!C53*(1-'前提と出典'!$B$21) -> 0.135 | E8: =ROUNDUP('前提と出典'!B53*'前提と出典'!$B$23,0) -> 8 | F8: ='前提と出典'!A53 -> 3 | G8: =MAX(1,ROUNDUP(E8*'前提と出典'!$B$25*'前提と出典'!E10,0)) -> 2 | H8: =IF(AND(F8>=1,F8<=100),1,0) -> 1 | I8: =IF(G8<=50,1,0) -> 1 | J8: =H8*I8 -> 1 | K8: =IF(A8='前提と出典'!$B$14,D8,0) -> 0 | L8: =IF(H8=0,0,IF(F8<=INDEX('前提と出典'!B41:B43,'前提と出典'!$B$15+1),INDEX('前提と出典'!C41:C43,'前提と出典'!$B$15+1),IF(F8<=INDEX('前提と出典'!D41:D43,'前提と出典'!$B$15+1),INDEX('前提と出典'!E41:E43,'前提と出典'!$B$15+1),INDEX('前提と出典'!G41:G43,'前提と出典'!$B$15+1)))) -> 3500 | M8: =IF(H8=0,0,IF('前提と出典'!$B$33=1,MIN(F8,10)*300+MIN(MAX(0,F8-10),20)*250+MAX(0,F8-30)*200,F8*300)) -> 900 | N8: =IF(I8=0,0,IF(G8<=INDEX('前提と出典'!B46:B48,'前提と出典'!$B$16+1),INDEX('前提と出典'!C46:C48,'前提と出典'!$B$16+1),IF(G8<=INDEX('前提と出典'!D46:D48,'前提と出典'!$B$16+1),INDEX('前提と出典'!E46:E48,'前提と出典'!$B$16+1),IF(G8<=INDEX('前提と出典'!F46:F48,'前提と出典'!$B$16+1),INDEX('前提と出典'!G46:G48,'前提と出典'!$B$16+1),INDEX('前提と出典'!I46:I48,'前提と出典'!$B$16+1))))) -> 1200 | O8: =IF(I8=1,G8*'前提と出典'!$B$13,0) -> 400 | P8: =IF(J8=1,MIN('前提と出典'!$B$17,L8+N8),0) -> 1000 | Q8: =IF(J8=0,0,IF('前提と出典'!$B$19=0,P8*L8/(L8+N8),MIN(P8,L8))) -> 744.68085 | R8: =P8-Q8 -> 255.31915 | S8: =IF(H8=1,'前提と出典'!$B$11+F8*'前提と出典'!$B$12,0) -> 53 | T8: =IF(H8=1,('前提と出典'!$B$9+F8*'前提と出典'!$B$10)/60*'前提と出典'!$B$8,0) -> 553.33333 | U8: =IF(I8=1,INDEX('前提と出典'!B80:B83,'前提と出典'!$B$18+1)+G8*INDEX('前提と出典'!C80:C83,'前提と出典'!$B$18+1),0) -> 89.542049 | V8: =IF(I8=1,INDEX('前提と出典'!D80:D83,'前提と出典'!$B$18+1)+G8*INDEX('前提と出典'!E80:E83,'前提と出典'!$B$18+1),0) -> 546.66667 | W8: =L8-Q8 -> 2755.3191 | X8: =N8-R8 -> 944.68085
A9: 0 | B9: 2 | C9: 0 | D9: ='前提と出典'!C54*'前提と出典'!$B$21 -> 0.168 | E9: =ROUNDUP('前提と出典'!B54*'前提と出典'!$B$22,0) -> 38 | F9: ='前提と出典'!A54 -> 8 | G9: =MAX(1,ROUNDUP(E9*'前提と出典'!$B$24*'前提と出典'!E10,0)) -> 2 | H9: =IF(AND(F9>=1,F9<=100),1,0) -> 1 | I9: =IF(G9<=50,1,0) -> 1 | J9: =H9*I9 -> 1 | K9: =IF(A9='前提と出典'!$B$14,D9,0) -> 0 | L9: =IF(H9=0,0,IF(F9<=INDEX('前提と出典'!B41:B43,'前提と出典'!$B$15+1),INDEX('前提と出典'!C41:C43,'前提と出典'!$B$15+1),IF(F9<=INDEX('前提と出典'!D41:D43,'前提と出典'!$B$15+1),INDEX('前提と出典'!E41:E43,'前提と出典'!$B$15+1),INDEX('前提と出典'!G41:G43,'前提と出典'!$B$15+1)))) -> 3500 | M9: =IF(H9=0,0,IF('前提と出典'!$B$33=1,MIN(F9,10)*300+MIN(MAX(0,F9-10),20)*250+MAX(0,F9-30)*200,F9*300)) -> 2400 | N9: =IF(I9=0,0,IF(G9<=INDEX('前提と出典'!B46:B48,'前提と出典'!$B$16+1),INDEX('前提と出典'!C46:C48,'前提と出典'!$B$16+1),IF(G9<=INDEX('前提と出典'!D46:D48,'前提と出典'!$B$16+1),INDEX('前提と出典'!E46:E48,'前提と出典'!$B$16+1),IF(G9<=INDEX('前提と出典'!F46:F48,'前提と出典'!$B$16+1),INDEX('前提と出典'!G46:G48,'前提と出典'!$B$16+1),INDEX('前提と出典'!I46:I48,'前提と出典'!$B$16+1))))) -> 1200 | O9: =IF(I9=1,G9*'前提と出典'!$B$13,0) -> 400 | P9: =IF(J9=1,MIN('前提と出典'!$B$17,L9+N9),0) -> 1000 | Q9: =IF(J9=0,0,IF('前提と出典'!$B$19=0,P9*L9/(L9+N9),MIN(P9,L9))) -> 744.68085 | R9: =P9-Q9 -> 255.31915 | S9: =IF(H9=1,'前提と出典'!$B$11+F9*'前提と出典'!$B$12,0) -> 58 | T9: =IF(H9=1,('前提と出典'!$B$9+F9*'前提と出典'!$B$10)/60*'前提と出典'!$B$8,0) -> 586.66667 | U9: =IF(I9=1,INDEX('前提と出典'!B80:B83,'前提と出典'!$B$18+1)+G9*INDEX('前提と出典'!C80:C83,'前提と出典'!$B$18+1),0) -> 89.542049 | V9: =IF(I9=1,INDEX('前提と出典'!D80:D83,'前提と出典'!$B$18+1)+G9*INDEX('前提と出典'!E80:E83,'前提と出典'!$B$18+1),0) -> 546.66667 | W9: =L9-Q9 -> 2755.3191 | X9: =N9-R9 -> 944.68085
A10: 0 | B10: 2 | C10: 1 | D10: ='前提と出典'!C54*(1-'前提と出典'!$B$21) -> 0.072 | E10: =ROUNDUP('前提と出典'!B54*'前提と出典'!$B$23,0) -> 19 | F10: ='前提と出典'!A54 -> 8 | G10: =MAX(1,ROUNDUP(E10*'前提と出典'!$B$25*'前提と出典'!E10,0)) -> 3 | H10: =IF(AND(F10>=1,F10<=100),1,0) -> 1 | I10: =IF(G10<=50,1,0) -> 1 | J10: =H10*I10 -> 1 | K10: =IF(A10='前提と出典'!$B$14,D10,0) -> 0 | L10: =IF(H10=0,0,IF(F10<=INDEX('前提と出典'!B41:B43,'前提と出典'!$B$15+1),INDEX('前提と出典'!C41:C43,'前提と出典'!$B$15+1),IF(F10<=INDEX('前提と出典'!D41:D43,'前提と出典'!$B$15+1),INDEX('前提と出典'!E41:E43,'前提と出典'!$B$15+1),INDEX('前提と出典'!G41:G43,'前提と出典'!$B$15+1)))) -> 3500 | M10: =IF(H10=0,0,IF('前提と出典'!$B$33=1,MIN(F10,10)*300+MIN(MAX(0,F10-10),20)*250+MAX(0,F10-30)*200,F10*300)) -> 2400 | N10: =IF(I10=0,0,IF(G10<=INDEX('前提と出典'!B46:B48,'前提と出典'!$B$16+1),INDEX('前提と出典'!C46:C48,'前提と出典'!$B$16+1),IF(G10<=INDEX('前提と出典'!D46:D48,'前提と出典'!$B$16+1),INDEX('前提と出典'!E46:E48,'前提と出典'!$B$16+1),IF(G10<=INDEX('前提と出典'!F46:F48,'前提と出典'!$B$16+1),INDEX('前提と出典'!G46:G48,'前提と出典'!$B$16+1),INDEX('前提と出典'!I46:I48,'前提と出典'!$B$16+1))))) -> 1200 | O10: =IF(I10=1,G10*'前提と出典'!$B$13,0) -> 600 | P10: =IF(J10=1,MIN('前提と出典'!$B$17,L10+N10),0) -> 1000 | Q10: =IF(J10=0,0,IF('前提と出典'!$B$19=0,P10*L10/(L10+N10),MIN(P10,L10))) -> 744.68085 | R10: =P10-Q10 -> 255.31915 | S10: =IF(H10=1,'前提と出典'!$B$11+F10*'前提と出典'!$B$12,0) -> 58 | T10: =IF(H10=1,('前提と出典'!$B$9+F10*'前提と出典'!$B$10)/60*'前提と出典'!$B$8,0) -> 586.66667 | U10: =IF(I10=1,INDEX('前提と出典'!B80:B83,'前提と出典'!$B$18+1)+G10*INDEX('前提と出典'!C80:C83,'前提と出典'!$B$18+1),0) -> 109.31307 | V10: =IF(I10=1,INDEX('前提と出典'!D80:D83,'前提と出典'!$B$18+1)+G10*INDEX('前提と出典'!E80:E83,'前提と出典'!$B$18+1),0) -> 553.33333 | W10: =L10-Q10 -> 2755.3191 | X10: =N10-R10 -> 944.68085
A11: 0 | B11: 3 | C11: 0 | D11: ='前提と出典'!C55*'前提と出典'!$B$21 -> 0.063 | E11: =ROUNDUP('前提と出典'!B55*'前提と出典'!$B$22,0) -> 90 | F11: ='前提と出典'!A55 -> 18 | G11: =MAX(1,ROUNDUP(E11*'前提と出典'!$B$24*'前提と出典'!E10,0)) -> 5 | H11: =IF(AND(F11>=1,F11<=100),1,0) -> 1 | I11: =IF(G11<=50,1,0) -> 1 | J11: =H11*I11 -> 1 | K11: =IF(A11='前提と出典'!$B$14,D11,0) -> 0 | L11: =IF(H11=0,0,IF(F11<=INDEX('前提と出典'!B41:B43,'前提と出典'!$B$15+1),INDEX('前提と出典'!C41:C43,'前提と出典'!$B$15+1),IF(F11<=INDEX('前提と出典'!D41:D43,'前提と出典'!$B$15+1),INDEX('前提と出典'!E41:E43,'前提と出典'!$B$15+1),INDEX('前提と出典'!G41:G43,'前提と出典'!$B$15+1)))) -> 5000 | M11: =IF(H11=0,0,IF('前提と出典'!$B$33=1,MIN(F11,10)*300+MIN(MAX(0,F11-10),20)*250+MAX(0,F11-30)*200,F11*300)) -> 5000 | N11: =IF(I11=0,0,IF(G11<=INDEX('前提と出典'!B46:B48,'前提と出典'!$B$16+1),INDEX('前提と出典'!C46:C48,'前提と出典'!$B$16+1),IF(G11<=INDEX('前提と出典'!D46:D48,'前提と出典'!$B$16+1),INDEX('前提と出典'!E46:E48,'前提と出典'!$B$16+1),IF(G11<=INDEX('前提と出典'!F46:F48,'前提と出典'!$B$16+1),INDEX('前提と出典'!G46:G48,'前提と出典'!$B$16+1),INDEX('前提と出典'!I46:I48,'前提と出典'!$B$16+1))))) -> 1200 | O11: =IF(I11=1,G11*'前提と出典'!$B$13,0) -> 1000 | P11: =IF(J11=1,MIN('前提と出典'!$B$17,L11+N11),0) -> 1000 | Q11: =IF(J11=0,0,IF('前提と出典'!$B$19=0,P11*L11/(L11+N11),MIN(P11,L11))) -> 806.45161 | R11: =P11-Q11 -> 193.54839 | S11: =IF(H11=1,'前提と出典'!$B$11+F11*'前提と出典'!$B$12,0) -> 68 | T11: =IF(H11=1,('前提と出典'!$B$9+F11*'前提と出典'!$B$10)/60*'前提と出典'!$B$8,0) -> 653.33333 | U11: =IF(I11=1,INDEX('前提と出典'!B80:B83,'前提と出典'!$B$18+1)+G11*INDEX('前提と出典'!C80:C83,'前提と出典'!$B$18+1),0) -> 148.85512 | V11: =IF(I11=1,INDEX('前提と出典'!D80:D83,'前提と出典'!$B$18+1)+G11*INDEX('前提と出典'!E80:E83,'前提と出典'!$B$18+1),0) -> 566.66667 | W11: =L11-Q11 -> 4193.5484 | X11: =N11-R11 -> 1006.4516
A12: 0 | B12: 3 | C12: 1 | D12: ='前提と出典'!C55*(1-'前提と出典'!$B$21) -> 0.027 | E12: =ROUNDUP('前提と出典'!B55*'前提と出典'!$B$23,0) -> 45 | F12: ='前提と出典'!A55 -> 18 | G12: =MAX(1,ROUNDUP(E12*'前提と出典'!$B$25*'前提と出典'!E10,0)) -> 7 | H12: =IF(AND(F12>=1,F12<=100),1,0) -> 1 | I12: =IF(G12<=50,1,0) -> 1 | J12: =H12*I12 -> 1 | K12: =IF(A12='前提と出典'!$B$14,D12,0) -> 0 | L12: =IF(H12=0,0,IF(F12<=INDEX('前提と出典'!B41:B43,'前提と出典'!$B$15+1),INDEX('前提と出典'!C41:C43,'前提と出典'!$B$15+1),IF(F12<=INDEX('前提と出典'!D41:D43,'前提と出典'!$B$15+1),INDEX('前提と出典'!E41:E43,'前提と出典'!$B$15+1),INDEX('前提と出典'!G41:G43,'前提と出典'!$B$15+1)))) -> 5000 | M12: =IF(H12=0,0,IF('前提と出典'!$B$33=1,MIN(F12,10)*300+MIN(MAX(0,F12-10),20)*250+MAX(0,F12-30)*200,F12*300)) -> 5000 | N12: =IF(I12=0,0,IF(G12<=INDEX('前提と出典'!B46:B48,'前提と出典'!$B$16+1),INDEX('前提と出典'!C46:C48,'前提と出典'!$B$16+1),IF(G12<=INDEX('前提と出典'!D46:D48,'前提と出典'!$B$16+1),INDEX('前提と出典'!E46:E48,'前提と出典'!$B$16+1),IF(G12<=INDEX('前提と出典'!F46:F48,'前提と出典'!$B$16+1),INDEX('前提と出典'!G46:G48,'前提と出典'!$B$16+1),INDEX('前提と出典'!I46:I48,'前提と出典'!$B$16+1))))) -> 1200 | O12: =IF(I12=1,G12*'前提と出典'!$B$13,0) -> 1400 | P12: =IF(J12=1,MIN('前提と出典'!$B$17,L12+N12),0) -> 1000 | Q12: =IF(J12=0,0,IF('前提と出典'!$B$19=0,P12*L12/(L12+N12),MIN(P12,L12))) -> 806.45161 | R12: =P12-Q12 -> 193.54839 | S12: =IF(H12=1,'前提と出典'!$B$11+F12*'前提と出典'!$B$12,0) -> 68 | T12: =IF(H12=1,('前提と出典'!$B$9+F12*'前提と出典'!$B$10)/60*'前提と出典'!$B$8,0) -> 653.33333 | U12: =IF(I12=1,INDEX('前提と出典'!B80:B83,'前提と出典'!$B$18+1)+G12*INDEX('前提と出典'!C80:C83,'前提と出典'!$B$18+1),0) -> 188.39717 | V12: =IF(I12=1,INDEX('前提と出典'!D80:D83,'前提と出典'!$B$18+1)+G12*INDEX('前提と出典'!E80:E83,'前提と出典'!$B$18+1),0) -> 580 | W12: =L12-Q12 -> 4193.5484 | X12: =N12-R12 -> 1006.4516
A13: 0 | B13: 4 | C13: 0 | D13: ='前提と出典'!C56*'前提と出典'!$B$21 -> 0.0105 | E13: =ROUNDUP('前提と出典'!B56*'前提と出典'!$B$22,0) -> 180 | F13: ='前提と出典'!A56 -> 40 | G13: =MAX(1,ROUNDUP(E13*'前提と出典'!$B$24*'前提と出典'!E10,0)) -> 9 | H13: =IF(AND(F13>=1,F13<=100),1,0) -> 1 | I13: =IF(G13<=50,1,0) -> 1 | J13: =H13*I13 -> 1 | K13: =IF(A13='前提と出典'!$B$14,D13,0) -> 0 | L13: =IF(H13=0,0,IF(F13<=INDEX('前提と出典'!B41:B43,'前提と出典'!$B$15+1),INDEX('前提と出典'!C41:C43,'前提と出典'!$B$15+1),IF(F13<=INDEX('前提と出典'!D41:D43,'前提と出典'!$B$15+1),INDEX('前提と出典'!E41:E43,'前提と出典'!$B$15+1),INDEX('前提と出典'!G41:G43,'前提と出典'!$B$15+1)))) -> 5000 | M13: =IF(H13=0,0,IF('前提と出典'!$B$33=1,MIN(F13,10)*300+MIN(MAX(0,F13-10),20)*250+MAX(0,F13-30)*200,F13*300)) -> 10000 | N13: =IF(I13=0,0,IF(G13<=INDEX('前提と出典'!B46:B48,'前提と出典'!$B$16+1),INDEX('前提と出典'!C46:C48,'前提と出典'!$B$16+1),IF(G13<=INDEX('前提と出典'!D46:D48,'前提と出典'!$B$16+1),INDEX('前提と出典'!E46:E48,'前提と出典'!$B$16+1),IF(G13<=INDEX('前提と出典'!F46:F48,'前提と出典'!$B$16+1),INDEX('前提と出典'!G46:G48,'前提と出典'!$B$16+1),INDEX('前提と出典'!I46:I48,'前提と出典'!$B$16+1))))) -> 1200 | O13: =IF(I13=1,G13*'前提と出典'!$B$13,0) -> 1800 | P13: =IF(J13=1,MIN('前提と出典'!$B$17,L13+N13),0) -> 1000 | Q13: =IF(J13=0,0,IF('前提と出典'!$B$19=0,P13*L13/(L13+N13),MIN(P13,L13))) -> 806.45161 | R13: =P13-Q13 -> 193.54839 | S13: =IF(H13=1,'前提と出典'!$B$11+F13*'前提と出典'!$B$12,0) -> 90 | T13: =IF(H13=1,('前提と出典'!$B$9+F13*'前提と出典'!$B$10)/60*'前提と出典'!$B$8,0) -> 800 | U13: =IF(I13=1,INDEX('前提と出典'!B80:B83,'前提と出典'!$B$18+1)+G13*INDEX('前提と出典'!C80:C83,'前提と出典'!$B$18+1),0) -> 227.93922 | V13: =IF(I13=1,INDEX('前提と出典'!D80:D83,'前提と出典'!$B$18+1)+G13*INDEX('前提と出典'!E80:E83,'前提と出典'!$B$18+1),0) -> 593.33333 | W13: =L13-Q13 -> 4193.5484 | X13: =N13-R13 -> 1006.4516
A14: 0 | B14: 4 | C14: 1 | D14: ='前提と出典'!C56*(1-'前提と出典'!$B$21) -> 0.0045 | E14: =ROUNDUP('前提と出典'!B56*'前提と出典'!$B$23,0) -> 90 | F14: ='前提と出典'!A56 -> 40 | G14: =MAX(1,ROUNDUP(E14*'前提と出典'!$B$25*'前提と出典'!E10,0)) -> 14 | H14: =IF(AND(F14>=1,F14<=100),1,0) -> 1 | I14: =IF(G14<=50,1,0) -> 1 | J14: =H14*I14 -> 1 | K14: =IF(A14='前提と出典'!$B$14,D14,0) -> 0 | L14: =IF(H14=0,0,IF(F14<=INDEX('前提と出典'!B41:B43,'前提と出典'!$B$15+1),INDEX('前提と出典'!C41:C43,'前提と出典'!$B$15+1),IF(F14<=INDEX('前提と出典'!D41:D43,'前提と出典'!$B$15+1),INDEX('前提と出典'!E41:E43,'前提と出典'!$B$15+1),INDEX('前提と出典'!G41:G43,'前提と出典'!$B$15+1)))) -> 5000 | M14: =IF(H14=0,0,IF('前提と出典'!$B$33=1,MIN(F14,10)*300+MIN(MAX(0,F14-10),20)*250+MAX(0,F14-30)*200,F14*300)) -> 10000 | N14: =IF(I14=0,0,IF(G14<=INDEX('前提と出典'!B46:B48,'前提と出典'!$B$16+1),INDEX('前提と出典'!C46:C48,'前提と出典'!$B$16+1),IF(G14<=INDEX('前提と出典'!D46:D48,'前提と出典'!$B$16+1),INDEX('前提と出典'!E46:E48,'前提と出典'!$B$16+1),IF(G14<=INDEX('前提と出典'!F46:F48,'前提と出典'!$B$16+1),INDEX('前提と出典'!G46:G48,'前提と出典'!$B$16+1),INDEX('前提と出典'!I46:I48,'前提と出典'!$B$16+1))))) -> 2500 | O14: =IF(I14=1,G14*'前提と出典'!$B$13,0) -> 2800 | P14: =IF(J14=1,MIN('前提と出典'!$B$17,L14+N14),0) -> 1000 | Q14: =IF(J14=0,0,IF('前提と出典'!$B$19=0,P14*L14/(L14+N14),MIN(P14,L14))) -> 666.66667 | R14: =P14-Q14 -> 333.33333 | S14: =IF(H14=1,'前提と出典'!$B$11+F14*'前提と出典'!$B$12,0) -> 90 | T14: =IF(H14=1,('前提と出典'!$B$9+F14*'前提と出典'!$B$10)/60*'前提と出典'!$B$8,0) -> 800 | U14: =IF(I14=1,INDEX('前提と出典'!B80:B83,'前提と出典'!$B$18+1)+G14*INDEX('前提と出典'!C80:C83,'前提と出典'!$B$18+1),0) -> 326.79434 | V14: =IF(I14=1,INDEX('前提と出典'!D80:D83,'前提と出典'!$B$18+1)+G14*INDEX('前提と出典'!E80:E83,'前提と出典'!$B$18+1),0) -> 626.66667 | W14: =L14-Q14 -> 4333.3333 | X14: =N14-R14 -> 2166.6667
A15: 0 | B15: 5 | C15: 0 | D15: ='前提と出典'!C57*'前提と出典'!$B$21 -> 0.0028 | E15: =ROUNDUP('前提と出典'!B57*'前提と出典'!$B$22,0) -> 300 | F15: ='前提と出典'!A57 -> 70 | G15: =MAX(1,ROUNDUP(E15*'前提と出典'!$B$24*'前提と出典'!E10,0)) -> 15 | H15: =IF(AND(F15>=1,F15<=100),1,0) -> 1 | I15: =IF(G15<=50,1,0) -> 1 | J15: =H15*I15 -> 1 | K15: =IF(A15='前提と出典'!$B$14,D15,0) -> 0 | L15: =IF(H15=0,0,IF(F15<=INDEX('前提と出典'!B41:B43,'前提と出典'!$B$15+1),INDEX('前提と出典'!C41:C43,'前提と出典'!$B$15+1),IF(F15<=INDEX('前提と出典'!D41:D43,'前提と出典'!$B$15+1),INDEX('前提と出典'!E41:E43,'前提と出典'!$B$15+1),INDEX('前提と出典'!G41:G43,'前提と出典'!$B$15+1)))) -> 5000 | M15: =IF(H15=0,0,IF('前提と出典'!$B$33=1,MIN(F15,10)*300+MIN(MAX(0,F15-10),20)*250+MAX(0,F15-30)*200,F15*300)) -> 16000 | N15: =IF(I15=0,0,IF(G15<=INDEX('前提と出典'!B46:B48,'前提と出典'!$B$16+1),INDEX('前提と出典'!C46:C48,'前提と出典'!$B$16+1),IF(G15<=INDEX('前提と出典'!D46:D48,'前提と出典'!$B$16+1),INDEX('前提と出典'!E46:E48,'前提と出典'!$B$16+1),IF(G15<=INDEX('前提と出典'!F46:F48,'前提と出典'!$B$16+1),INDEX('前提と出典'!G46:G48,'前提と出典'!$B$16+1),INDEX('前提と出典'!I46:I48,'前提と出典'!$B$16+1))))) -> 2500 | O15: =IF(I15=1,G15*'前提と出典'!$B$13,0) -> 3000 | P15: =IF(J15=1,MIN('前提と出典'!$B$17,L15+N15),0) -> 1000 | Q15: =IF(J15=0,0,IF('前提と出典'!$B$19=0,P15*L15/(L15+N15),MIN(P15,L15))) -> 666.66667 | R15: =P15-Q15 -> 333.33333 | S15: =IF(H15=1,'前提と出典'!$B$11+F15*'前提と出典'!$B$12,0) -> 120 | T15: =IF(H15=1,('前提と出典'!$B$9+F15*'前提と出典'!$B$10)/60*'前提と出典'!$B$8,0) -> 1000 | U15: =IF(I15=1,INDEX('前提と出典'!B80:B83,'前提と出典'!$B$18+1)+G15*INDEX('前提と出典'!C80:C83,'前提と出典'!$B$18+1),0) -> 346.56537 | V15: =IF(I15=1,INDEX('前提と出典'!D80:D83,'前提と出典'!$B$18+1)+G15*INDEX('前提と出典'!E80:E83,'前提と出典'!$B$18+1),0) -> 633.33333 | W15: =L15-Q15 -> 4333.3333 | X15: =N15-R15 -> 2166.6667
A16: 0 | B16: 5 | C16: 1 | D16: ='前提と出典'!C57*(1-'前提と出典'!$B$21) -> 0.0012 | E16: =ROUNDUP('前提と出典'!B57*'前提と出典'!$B$23,0) -> 150 | F16: ='前提と出典'!A57 -> 70 | G16: =MAX(1,ROUNDUP(E16*'前提と出典'!$B$25*'前提と出典'!E10,0)) -> 23 | H16: =IF(AND(F16>=1,F16<=100),1,0) -> 1 | I16: =IF(G16<=50,1,0) -> 1 | J16: =H16*I16 -> 1 | K16: =IF(A16='前提と出典'!$B$14,D16,0) -> 0 | L16: =IF(H16=0,0,IF(F16<=INDEX('前提と出典'!B41:B43,'前提と出典'!$B$15+1),INDEX('前提と出典'!C41:C43,'前提と出典'!$B$15+1),IF(F16<=INDEX('前提と出典'!D41:D43,'前提と出典'!$B$15+1),INDEX('前提と出典'!E41:E43,'前提と出典'!$B$15+1),INDEX('前提と出典'!G41:G43,'前提と出典'!$B$15+1)))) -> 5000 | M16: =IF(H16=0,0,IF('前提と出典'!$B$33=1,MIN(F16,10)*300+MIN(MAX(0,F16-10),20)*250+MAX(0,F16-30)*200,F16*300)) -> 16000 | N16: =IF(I16=0,0,IF(G16<=INDEX('前提と出典'!B46:B48,'前提と出典'!$B$16+1),INDEX('前提と出典'!C46:C48,'前提と出典'!$B$16+1),IF(G16<=INDEX('前提と出典'!D46:D48,'前提と出典'!$B$16+1),INDEX('前提と出典'!E46:E48,'前提と出典'!$B$16+1),IF(G16<=INDEX('前提と出典'!F46:F48,'前提と出典'!$B$16+1),INDEX('前提と出典'!G46:G48,'前提と出典'!$B$16+1),INDEX('前提と出典'!I46:I48,'前提と出典'!$B$16+1))))) -> 2500 | O16: =IF(I16=1,G16*'前提と出典'!$B$13,0) -> 4600 | P16: =IF(J16=1,MIN('前提と出典'!$B$17,L16+N16),0) -> 1000 | Q16: =IF(J16=0,0,IF('前提と出典'!$B$19=0,P16*L16/(L16+N16),MIN(P16,L16))) -> 666.66667 | R16: =P16-Q16 -> 333.33333 | S16: =IF(H16=1,'前提と出典'!$B$11+F16*'前提と出典'!$B$12,0) -> 120 | T16: =IF(H16=1,('前提と出典'!$B$9+F16*'前提と出典'!$B$10)/60*'前提と出典'!$B$8,0) -> 1000 | U16: =IF(I16=1,INDEX('前提と出典'!B80:B83,'前提と出典'!$B$18+1)+G16*INDEX('前提と出典'!C80:C83,'前提と出典'!$B$18+1),0) -> 504.73356 | V16: =IF(I16=1,INDEX('前提と出典'!D80:D83,'前提と出典'!$B$18+1)+G16*INDEX('前提と出典'!E80:E83,'前提と出典'!$B$18+1),0) -> 686.66667 | W16: =L16-Q16 -> 4333.3333 | X16: =N16-R16 -> 2166.6667
A17: 0 | B17: 6 | C17: 0 | D17: ='前提と出典'!C58*'前提と出典'!$B$21 -> 0.0007 | E17: =ROUNDUP('前提と出典'!B58*'前提と出典'!$B$22,0) -> 600 | F17: ='前提と出典'!A58 -> 130 | G17: =MAX(1,ROUNDUP(E17*'前提と出典'!$B$24*'前提と出典'!E10,0)) -> 30 | H17: =IF(AND(F17>=1,F17<=100),1,0) -> 0 | I17: =IF(G17<=50,1,0) -> 1 | J17: =H17*I17 -> 0 | K17: =IF(A17='前提と出典'!$B$14,D17,0) -> 0 | L17: =IF(H17=0,0,IF(F17<=INDEX('前提と出典'!B41:B43,'前提と出典'!$B$15+1),INDEX('前提と出典'!C41:C43,'前提と出典'!$B$15+1),IF(F17<=INDEX('前提と出典'!D41:D43,'前提と出典'!$B$15+1),INDEX('前提と出典'!E41:E43,'前提と出典'!$B$15+1),INDEX('前提と出典'!G41:G43,'前提と出典'!$B$15+1)))) -> 0 | M17: =IF(H17=0,0,IF('前提と出典'!$B$33=1,MIN(F17,10)*300+MIN(MAX(0,F17-10),20)*250+MAX(0,F17-30)*200,F17*300)) -> 0 | N17: =IF(I17=0,0,IF(G17<=INDEX('前提と出典'!B46:B48,'前提と出典'!$B$16+1),INDEX('前提と出典'!C46:C48,'前提と出典'!$B$16+1),IF(G17<=INDEX('前提と出典'!D46:D48,'前提と出典'!$B$16+1),INDEX('前提と出典'!E46:E48,'前提と出典'!$B$16+1),IF(G17<=INDEX('前提と出典'!F46:F48,'前提と出典'!$B$16+1),INDEX('前提と出典'!G46:G48,'前提と出典'!$B$16+1),INDEX('前提と出典'!I46:I48,'前提と出典'!$B$16+1))))) -> 2500 | O17: =IF(I17=1,G17*'前提と出典'!$B$13,0) -> 6000 | P17: =IF(J17=1,MIN('前提と出典'!$B$17,L17+N17),0) -> 0 | Q17: =IF(J17=0,0,IF('前提と出典'!$B$19=0,P17*L17/(L17+N17),MIN(P17,L17))) -> 0 | R17: =P17-Q17 -> 0 | S17: =IF(H17=1,'前提と出典'!$B$11+F17*'前提と出典'!$B$12,0) -> 0 | T17: =IF(H17=1,('前提と出典'!$B$9+F17*'前提と出典'!$B$10)/60*'前提と出典'!$B$8,0) -> 0 | U17: =IF(I17=1,INDEX('前提と出典'!B80:B83,'前提と出典'!$B$18+1)+G17*INDEX('前提と出典'!C80:C83,'前提と出典'!$B$18+1),0) -> 643.13073 | V17: =IF(I17=1,INDEX('前提と出典'!D80:D83,'前提と出典'!$B$18+1)+G17*INDEX('前提と出典'!E80:E83,'前提と出典'!$B$18+1),0) -> 733.33333 | W17: =L17-Q17 -> 0 | X17: =N17-R17 -> 2500
A18: 0 | B18: 6 | C18: 1 | D18: ='前提と出典'!C58*(1-'前提と出典'!$B$21) -> 0.0003 | E18: =ROUNDUP('前提と出典'!B58*'前提と出典'!$B$23,0) -> 300 | F18: ='前提と出典'!A58 -> 130 | G18: =MAX(1,ROUNDUP(E18*'前提と出典'!$B$25*'前提と出典'!E10,0)) -> 45 | H18: =IF(AND(F18>=1,F18<=100),1,0) -> 0 | I18: =IF(G18<=50,1,0) -> 1 | J18: =H18*I18 -> 0 | K18: =IF(A18='前提と出典'!$B$14,D18,0) -> 0 | L18: =IF(H18=0,0,IF(F18<=INDEX('前提と出典'!B41:B43,'前提と出典'!$B$15+1),INDEX('前提と出典'!C41:C43,'前提と出典'!$B$15+1),IF(F18<=INDEX('前提と出典'!D41:D43,'前提と出典'!$B$15+1),INDEX('前提と出典'!E41:E43,'前提と出典'!$B$15+1),INDEX('前提と出典'!G41:G43,'前提と出典'!$B$15+1)))) -> 0 | M18: =IF(H18=0,0,IF('前提と出典'!$B$33=1,MIN(F18,10)*300+MIN(MAX(0,F18-10),20)*250+MAX(0,F18-30)*200,F18*300)) -> 0 | N18: =IF(I18=0,0,IF(G18<=INDEX('前提と出典'!B46:B48,'前提と出典'!$B$16+1),INDEX('前提と出典'!C46:C48,'前提と出典'!$B$16+1),IF(G18<=INDEX('前提と出典'!D46:D48,'前提と出典'!$B$16+1),INDEX('前提と出典'!E46:E48,'前提と出典'!$B$16+1),IF(G18<=INDEX('前提と出典'!F46:F48,'前提と出典'!$B$16+1),INDEX('前提と出典'!G46:G48,'前提と出典'!$B$16+1),INDEX('前提と出典'!I46:I48,'前提と出典'!$B$16+1))))) -> 2500 | O18: =IF(I18=1,G18*'前提と出典'!$B$13,0) -> 9000 | P18: =IF(J18=1,MIN('前提と出典'!$B$17,L18+N18),0) -> 0 | Q18: =IF(J18=0,0,IF('前提と出典'!$B$19=0,P18*L18/(L18+N18),MIN(P18,L18))) -> 0 | R18: =P18-Q18 -> 0 | S18: =IF(H18=1,'前提と出典'!$B$11+F18*'前提と出典'!$B$12,0) -> 0 | T18: =IF(H18=1,('前提と出典'!$B$9+F18*'前提と出典'!$B$10)/60*'前提と出典'!$B$8,0) -> 0 | U18: =IF(I18=1,INDEX('前提と出典'!B80:B83,'前提と出典'!$B$18+1)+G18*INDEX('前提と出典'!C80:C83,'前提と出典'!$B$18+1),0) -> 939.6961 | V18: =IF(I18=1,INDEX('前提と出典'!D80:D83,'前提と出典'!$B$18+1)+G18*INDEX('前提と出典'!E80:E83,'前提と出典'!$B$18+1),0) -> 833.33333 | W18: =L18-Q18 -> 0 | X18: =N18-R18 -> 2500
A19: 1 | B19: 0 | C19: 0 | D19: ='前提と出典'!D52*'前提と出典'!$B$21 -> 0.07 | E19: =ROUNDUP('前提と出典'!B52*'前提と出典'!$B$22,0) -> 6 | F19: ='前提と出典'!A52 -> 0 | G19: =MAX(1,ROUNDUP(E19*'前提と出典'!$B$24*'前提と出典'!E11,0)) -> 1 | H19: =IF(AND(F19>=1,F19<=100),1,0) -> 0 | I19: =IF(G19<=50,1,0) -> 1 | J19: =H19*I19 -> 0 | K19: =IF(A19='前提と出典'!$B$14,D19,0) -> 0.07 | L19: =IF(H19=0,0,IF(F19<=INDEX('前提と出典'!B41:B43,'前提と出典'!$B$15+1),INDEX('前提と出典'!C41:C43,'前提と出典'!$B$15+1),IF(F19<=INDEX('前提と出典'!D41:D43,'前提と出典'!$B$15+1),INDEX('前提と出典'!E41:E43,'前提と出典'!$B$15+1),INDEX('前提と出典'!G41:G43,'前提と出典'!$B$15+1)))) -> 0 | M19: =IF(H19=0,0,IF('前提と出典'!$B$33=1,MIN(F19,10)*300+MIN(MAX(0,F19-10),20)*250+MAX(0,F19-30)*200,F19*300)) -> 0 | N19: =IF(I19=0,0,IF(G19<=INDEX('前提と出典'!B46:B48,'前提と出典'!$B$16+1),INDEX('前提と出典'!C46:C48,'前提と出典'!$B$16+1),IF(G19<=INDEX('前提と出典'!D46:D48,'前提と出典'!$B$16+1),INDEX('前提と出典'!E46:E48,'前提と出典'!$B$16+1),IF(G19<=INDEX('前提と出典'!F46:F48,'前提と出典'!$B$16+1),INDEX('前提と出典'!G46:G48,'前提と出典'!$B$16+1),INDEX('前提と出典'!I46:I48,'前提と出典'!$B$16+1))))) -> 1200 | O19: =IF(I19=1,G19*'前提と出典'!$B$13,0) -> 200 | P19: =IF(J19=1,MIN('前提と出典'!$B$17,L19+N19),0) -> 0 | Q19: =IF(J19=0,0,IF('前提と出典'!$B$19=0,P19*L19/(L19+N19),MIN(P19,L19))) -> 0 | R19: =P19-Q19 -> 0 | S19: =IF(H19=1,'前提と出典'!$B$11+F19*'前提と出典'!$B$12,0) -> 0 | T19: =IF(H19=1,('前提と出典'!$B$9+F19*'前提と出典'!$B$10)/60*'前提と出典'!$B$8,0) -> 0 | U19: =IF(I19=1,INDEX('前提と出典'!B80:B83,'前提と出典'!$B$18+1)+G19*INDEX('前提と出典'!C80:C83,'前提と出典'!$B$18+1),0) -> 69.771024 | V19: =IF(I19=1,INDEX('前提と出典'!D80:D83,'前提と出典'!$B$18+1)+G19*INDEX('前提と出典'!E80:E83,'前提と出典'!$B$18+1),0) -> 540 | W19: =L19-Q19 -> 0 | X19: =N19-R19 -> 1200
A20: 1 | B20: 0 | C20: 1 | D20: ='前提と出典'!D52*(1-'前提と出典'!$B$21) -> 0.03 | E20: =ROUNDUP('前提と出典'!B52*'前提と出典'!$B$23,0) -> 3 | F20: ='前提と出典'!A52 -> 0 | G20: =MAX(1,ROUNDUP(E20*'前提と出典'!$B$25*'前提と出典'!E11,0)) -> 1 | H20: =IF(AND(F20>=1,F20<=100),1,0) -> 0 | I20: =IF(G20<=50,1,0) -> 1 | J20: =H20*I20 -> 0 | K20: =IF(A20='前提と出典'!$B$14,D20,0) -> 0.03 | L20: =IF(H20=0,0,IF(F20<=INDEX('前提と出典'!B41:B43,'前提と出典'!$B$15+1),INDEX('前提と出典'!C41:C43,'前提と出典'!$B$15+1),IF(F20<=INDEX('前提と出典'!D41:D43,'前提と出典'!$B$15+1),INDEX('前提と出典'!E41:E43,'前提と出典'!$B$15+1),INDEX('前提と出典'!G41:G43,'前提と出典'!$B$15+1)))) -> 0 | M20: =IF(H20=0,0,IF('前提と出典'!$B$33=1,MIN(F20,10)*300+MIN(MAX(0,F20-10),20)*250+MAX(0,F20-30)*200,F20*300)) -> 0 | N20: =IF(I20=0,0,IF(G20<=INDEX('前提と出典'!B46:B48,'前提と出典'!$B$16+1),INDEX('前提と出典'!C46:C48,'前提と出典'!$B$16+1),IF(G20<=INDEX('前提と出典'!D46:D48,'前提と出典'!$B$16+1),INDEX('前提と出典'!E46:E48,'前提と出典'!$B$16+1),IF(G20<=INDEX('前提と出典'!F46:F48,'前提と出典'!$B$16+1),INDEX('前提と出典'!G46:G48,'前提と出典'!$B$16+1),INDEX('前提と出典'!I46:I48,'前提と出典'!$B$16+1))))) -> 1200 | O20: =IF(I20=1,G20*'前提と出典'!$B$13,0) -> 200 | P20: =IF(J20=1,MIN('前提と出典'!$B$17,L20+N20),0) -> 0 | Q20: =IF(J20=0,0,IF('前提と出典'!$B$19=0,P20*L20/(L20+N20),MIN(P20,L20))) -> 0 | R20: =P20-Q20 -> 0 | S20: =IF(H20=1,'前提と出典'!$B$11+F20*'前提と出典'!$B$12,0) -> 0 | T20: =IF(H20=1,('前提と出典'!$B$9+F20*'前提と出典'!$B$10)/60*'前提と出典'!$B$8,0) -> 0 | U20: =IF(I20=1,INDEX('前提と出典'!B80:B83,'前提と出典'!$B$18+1)+G20*INDEX('前提と出典'!C80:C83,'前提と出典'!$B$18+1),0) -> 69.771024 | V20: =IF(I20=1,INDEX('前提と出典'!D80:D83,'前提と出典'!$B$18+1)+G20*INDEX('前提と出典'!E80:E83,'前提と出典'!$B$18+1),0) -> 540 | W20: =L20-Q20 -> 0 | X20: =N20-R20 -> 1200
A21: 1 | B21: 1 | C21: 0 | D21: ='前提と出典'!D53*'前提と出典'!$B$21 -> 0.259 | E21: =ROUNDUP('前提と出典'!B53*'前提と出典'!$B$22,0) -> 15 | F21: ='前提と出典'!A53 -> 3 | G21: =MAX(1,ROUNDUP(E21*'前提と出典'!$B$24*'前提と出典'!E11,0)) -> 2 | H21: =IF(AND(F21>=1,F21<=100),1,0) -> 1 | I21: =IF(G21<=50,1,0) -> 1 | J21: =H21*I21 -> 1 | K21: =IF(A21='前提と出典'!$B$14,D21,0) -> 0.259 | L21: =IF(H21=0,0,IF(F21<=INDEX('前提と出典'!B41:B43,'前提と出典'!$B$15+1),INDEX('前提と出典'!C41:C43,'前提と出典'!$B$15+1),IF(F21<=INDEX('前提と出典'!D41:D43,'前提と出典'!$B$15+1),INDEX('前提と出典'!E41:E43,'前提と出典'!$B$15+1),INDEX('前提と出典'!G41:G43,'前提と出典'!$B$15+1)))) -> 3500 | M21: =IF(H21=0,0,IF('前提と出典'!$B$33=1,MIN(F21,10)*300+MIN(MAX(0,F21-10),20)*250+MAX(0,F21-30)*200,F21*300)) -> 900 | N21: =IF(I21=0,0,IF(G21<=INDEX('前提と出典'!B46:B48,'前提と出典'!$B$16+1),INDEX('前提と出典'!C46:C48,'前提と出典'!$B$16+1),IF(G21<=INDEX('前提と出典'!D46:D48,'前提と出典'!$B$16+1),INDEX('前提と出典'!E46:E48,'前提と出典'!$B$16+1),IF(G21<=INDEX('前提と出典'!F46:F48,'前提と出典'!$B$16+1),INDEX('前提と出典'!G46:G48,'前提と出典'!$B$16+1),INDEX('前提と出典'!I46:I48,'前提と出典'!$B$16+1))))) -> 1200 | O21: =IF(I21=1,G21*'前提と出典'!$B$13,0) -> 400 | P21: =IF(J21=1,MIN('前提と出典'!$B$17,L21+N21),0) -> 1000 | Q21: =IF(J21=0,0,IF('前提と出典'!$B$19=0,P21*L21/(L21+N21),MIN(P21,L21))) -> 744.68085 | R21: =P21-Q21 -> 255.31915 | S21: =IF(H21=1,'前提と出典'!$B$11+F21*'前提と出典'!$B$12,0) -> 53 | T21: =IF(H21=1,('前提と出典'!$B$9+F21*'前提と出典'!$B$10)/60*'前提と出典'!$B$8,0) -> 553.33333 | U21: =IF(I21=1,INDEX('前提と出典'!B80:B83,'前提と出典'!$B$18+1)+G21*INDEX('前提と出典'!C80:C83,'前提と出典'!$B$18+1),0) -> 89.542049 | V21: =IF(I21=1,INDEX('前提と出典'!D80:D83,'前提と出典'!$B$18+1)+G21*INDEX('前提と出典'!E80:E83,'前提と出典'!$B$18+1),0) -> 546.66667 | W21: =L21-Q21 -> 2755.3191 | X21: =N21-R21 -> 944.68085
A22: 1 | B22: 1 | C22: 1 | D22: ='前提と出典'!D53*(1-'前提と出典'!$B$21) -> 0.111 | E22: =ROUNDUP('前提と出典'!B53*'前提と出典'!$B$23,0) -> 8 | F22: ='前提と出典'!A53 -> 3 | G22: =MAX(1,ROUNDUP(E22*'前提と出典'!$B$25*'前提と出典'!E11,0)) -> 3 | H22: =IF(AND(F22>=1,F22<=100),1,0) -> 1 | I22: =IF(G22<=50,1,0) -> 1 | J22: =H22*I22 -> 1 | K22: =IF(A22='前提と出典'!$B$14,D22,0) -> 0.111 | L22: =IF(H22=0,0,IF(F22<=INDEX('前提と出典'!B41:B43,'前提と出典'!$B$15+1),INDEX('前提と出典'!C41:C43,'前提と出典'!$B$15+1),IF(F22<=INDEX('前提と出典'!D41:D43,'前提と出典'!$B$15+1),INDEX('前提と出典'!E41:E43,'前提と出典'!$B$15+1),INDEX('前提と出典'!G41:G43,'前提と出典'!$B$15+1)))) -> 3500 | M22: =IF(H22=0,0,IF('前提と出典'!$B$33=1,MIN(F22,10)*300+MIN(MAX(0,F22-10),20)*250+MAX(0,F22-30)*200,F22*300)) -> 900 | N22: =IF(I22=0,0,IF(G22<=INDEX('前提と出典'!B46:B48,'前提と出典'!$B$16+1),INDEX('前提と出典'!C46:C48,'前提と出典'!$B$16+1),IF(G22<=INDEX('前提と出典'!D46:D48,'前提と出典'!$B$16+1),INDEX('前提と出典'!E46:E48,'前提と出典'!$B$16+1),IF(G22<=INDEX('前提と出典'!F46:F48,'前提と出典'!$B$16+1),INDEX('前提と出典'!G46:G48,'前提と出典'!$B$16+1),INDEX('前提と出典'!I46:I48,'前提と出典'!$B$16+1))))) -> 1200 | O22: =IF(I22=1,G22*'前提と出典'!$B$13,0) -> 600 | P22: =IF(J22=1,MIN('前提と出典'!$B$17,L22+N22),0) -> 1000 | Q22: =IF(J22=0,0,IF('前提と出典'!$B$19=0,P22*L22/(L22+N22),MIN(P22,L22))) -> 744.68085 | R22: =P22-Q22 -> 255.31915 | S22: =IF(H22=1,'前提と出典'!$B$11+F22*'前提と出典'!$B$12,0) -> 53 | T22: =IF(H22=1,('前提と出典'!$B$9+F22*'前提と出典'!$B$10)/60*'前提と出典'!$B$8,0) -> 553.33333 | U22: =IF(I22=1,INDEX('前提と出典'!B80:B83,'前提と出典'!$B$18+1)+G22*INDEX('前提と出典'!C80:C83,'前提と出典'!$B$18+1),0) -> 109.31307 | V22: =IF(I22=1,INDEX('前提と出典'!D80:D83,'前提と出典'!$B$18+1)+G22*INDEX('前提と出典'!E80:E83,'前提と出典'!$B$18+1),0) -> 553.33333 | W22: =L22-Q22 -> 2755.3191 | X22: =N22-R22 -> 944.68085
A23: 1 | B23: 2 | C23: 0 | D23: ='前提と出典'!D54*'前提と出典'!$B$21 -> 0.196 | E23: =ROUNDUP('前提と出典'!B54*'前提と出典'!$B$22,0) -> 38 | F23: ='前提と出典'!A54 -> 8 | G23: =MAX(1,ROUNDUP(E23*'前提と出典'!$B$24*'前提と出典'!E11,0)) -> 4 | H23: =IF(AND(F23>=1,F23<=100),1,0) -> 1 | I23: =IF(G23<=50,1,0) -> 1 | J23: =H23*I23 -> 1 | K23: =IF(A23='前提と出典'!$B$14,D23,0) -> 0.196 | L23: =IF(H23=0,0,IF(F23<=INDEX('前提と出典'!B41:B43,'前提と出典'!$B$15+1),INDEX('前提と出典'!C41:C43,'前提と出典'!$B$15+1),IF(F23<=INDEX('前提と出典'!D41:D43,'前提と出典'!$B$15+1),INDEX('前提と出典'!E41:E43,'前提と出典'!$B$15+1),INDEX('前提と出典'!G41:G43,'前提と出典'!$B$15+1)))) -> 3500 | M23: =IF(H23=0,0,IF('前提と出典'!$B$33=1,MIN(F23,10)*300+MIN(MAX(0,F23-10),20)*250+MAX(0,F23-30)*200,F23*300)) -> 2400 | N23: =IF(I23=0,0,IF(G23<=INDEX('前提と出典'!B46:B48,'前提と出典'!$B$16+1),INDEX('前提と出典'!C46:C48,'前提と出典'!$B$16+1),IF(G23<=INDEX('前提と出典'!D46:D48,'前提と出典'!$B$16+1),INDEX('前提と出典'!E46:E48,'前提と出典'!$B$16+1),IF(G23<=INDEX('前提と出典'!F46:F48,'前提と出典'!$B$16+1),INDEX('前提と出典'!G46:G48,'前提と出典'!$B$16+1),INDEX('前提と出典'!I46:I48,'前提と出典'!$B$16+1))))) -> 1200 | O23: =IF(I23=1,G23*'前提と出典'!$B$13,0) -> 800 | P23: =IF(J23=1,MIN('前提と出典'!$B$17,L23+N23),0) -> 1000 | Q23: =IF(J23=0,0,IF('前提と出典'!$B$19=0,P23*L23/(L23+N23),MIN(P23,L23))) -> 744.68085 | R23: =P23-Q23 -> 255.31915 | S23: =IF(H23=1,'前提と出典'!$B$11+F23*'前提と出典'!$B$12,0) -> 58 | T23: =IF(H23=1,('前提と出典'!$B$9+F23*'前提と出典'!$B$10)/60*'前提と出典'!$B$8,0) -> 586.66667 | U23: =IF(I23=1,INDEX('前提と出典'!B80:B83,'前提と出典'!$B$18+1)+G23*INDEX('前提と出典'!C80:C83,'前提と出典'!$B$18+1),0) -> 129.0841 | V23: =IF(I23=1,INDEX('前提と出典'!D80:D83,'前提と出典'!$B$18+1)+G23*INDEX('前提と出典'!E80:E83,'前提と出典'!$B$18+1),0) -> 560 | W23: =L23-Q23 -> 2755.3191 | X23: =N23-R23 -> 944.68085
A24: 1 | B24: 2 | C24: 1 | D24: ='前提と出典'!D54*(1-'前提と出典'!$B$21) -> 0.084 | E24: =ROUNDUP('前提と出典'!B54*'前提と出典'!$B$23,0) -> 19 | F24: ='前提と出典'!A54 -> 8 | G24: =MAX(1,ROUNDUP(E24*'前提と出典'!$B$25*'前提と出典'!E11,0)) -> 6 | H24: =IF(AND(F24>=1,F24<=100),1,0) -> 1 | I24: =IF(G24<=50,1,0) -> 1 | J24: =H24*I24 -> 1 | K24: =IF(A24='前提と出典'!$B$14,D24,0) -> 0.084 | L24: =IF(H24=0,0,IF(F24<=INDEX('前提と出典'!B41:B43,'前提と出典'!$B$15+1),INDEX('前提と出典'!C41:C43,'前提と出典'!$B$15+1),IF(F24<=INDEX('前提と出典'!D41:D43,'前提と出典'!$B$15+1),INDEX('前提と出典'!E41:E43,'前提と出典'!$B$15+1),INDEX('前提と出典'!G41:G43,'前提と出典'!$B$15+1)))) -> 3500 | M24: =IF(H24=0,0,IF('前提と出典'!$B$33=1,MIN(F24,10)*300+MIN(MAX(0,F24-10),20)*250+MAX(0,F24-30)*200,F24*300)) -> 2400 | N24: =IF(I24=0,0,IF(G24<=INDEX('前提と出典'!B46:B48,'前提と出典'!$B$16+1),INDEX('前提と出典'!C46:C48,'前提と出典'!$B$16+1),IF(G24<=INDEX('前提と出典'!D46:D48,'前提と出典'!$B$16+1),INDEX('前提と出典'!E46:E48,'前提と出典'!$B$16+1),IF(G24<=INDEX('前提と出典'!F46:F48,'前提と出典'!$B$16+1),INDEX('前提と出典'!G46:G48,'前提と出典'!$B$16+1),INDEX('前提と出典'!I46:I48,'前提と出典'!$B$16+1))))) -> 1200 | O24: =IF(I24=1,G24*'前提と出典'!$B$13,0) -> 1200 | P24: =IF(J24=1,MIN('前提と出典'!$B$17,L24+N24),0) -> 1000 | Q24: =IF(J24=0,0,IF('前提と出典'!$B$19=0,P24*L24/(L24+N24),MIN(P24,L24))) -> 744.68085 | R24: =P24-Q24 -> 255.31915 | S24: =IF(H24=1,'前提と出典'!$B$11+F24*'前提と出典'!$B$12,0) -> 58 | T24: =IF(H24=1,('前提と出典'!$B$9+F24*'前提と出典'!$B$10)/60*'前提と出典'!$B$8,0) -> 586.66667 | U24: =IF(I24=1,INDEX('前提と出典'!B80:B83,'前提と出典'!$B$18+1)+G24*INDEX('前提と出典'!C80:C83,'前提と出典'!$B$18+1),0) -> 168.62615 | V24: =IF(I24=1,INDEX('前提と出典'!D80:D83,'前提と出典'!$B$18+1)+G24*INDEX('前提と出典'!E80:E83,'前提と出典'!$B$18+1),0) -> 573.33333 | W24: =L24-Q24 -> 2755.3191 | X24: =N24-R24 -> 944.68085
A25: 1 | B25: 3 | C25: 0 | D25: ='前提と出典'!D55*'前提と出典'!$B$21 -> 0.14 | E25: =ROUNDUP('前提と出典'!B55*'前提と出典'!$B$22,0) -> 90 | F25: ='前提と出典'!A55 -> 18 | G25: =MAX(1,ROUNDUP(E25*'前提と出典'!$B$24*'前提と出典'!E11,0)) -> 9 | H25: =IF(AND(F25>=1,F25<=100),1,0) -> 1 | I25: =IF(G25<=50,1,0) -> 1 | J25: =H25*I25 -> 1 | K25: =IF(A25='前提と出典'!$B$14,D25,0) -> 0.14 | L25: =IF(H25=0,0,IF(F25<=INDEX('前提と出典'!B41:B43,'前提と出典'!$B$15+1),INDEX('前提と出典'!C41:C43,'前提と出典'!$B$15+1),IF(F25<=INDEX('前提と出典'!D41:D43,'前提と出典'!$B$15+1),INDEX('前提と出典'!E41:E43,'前提と出典'!$B$15+1),INDEX('前提と出典'!G41:G43,'前提と出典'!$B$15+1)))) -> 5000 | M25: =IF(H25=0,0,IF('前提と出典'!$B$33=1,MIN(F25,10)*300+MIN(MAX(0,F25-10),20)*250+MAX(0,F25-30)*200,F25*300)) -> 5000 | N25: =IF(I25=0,0,IF(G25<=INDEX('前提と出典'!B46:B48,'前提と出典'!$B$16+1),INDEX('前提と出典'!C46:C48,'前提と出典'!$B$16+1),IF(G25<=INDEX('前提と出典'!D46:D48,'前提と出典'!$B$16+1),INDEX('前提と出典'!E46:E48,'前提と出典'!$B$16+1),IF(G25<=INDEX('前提と出典'!F46:F48,'前提と出典'!$B$16+1),INDEX('前提と出典'!G46:G48,'前提と出典'!$B$16+1),INDEX('前提と出典'!I46:I48,'前提と出典'!$B$16+1))))) -> 1200 | O25: =IF(I25=1,G25*'前提と出典'!$B$13,0) -> 1800 | P25: =IF(J25=1,MIN('前提と出典'!$B$17,L25+N25),0) -> 1000 | Q25: =IF(J25=0,0,IF('前提と出典'!$B$19=0,P25*L25/(L25+N25),MIN(P25,L25))) -> 806.45161 | R25: =P25-Q25 -> 193.54839 | S25: =IF(H25=1,'前提と出典'!$B$11+F25*'前提と出典'!$B$12,0) -> 68 | T25: =IF(H25=1,('前提と出典'!$B$9+F25*'前提と出典'!$B$10)/60*'前提と出典'!$B$8,0) -> 653.33333 | U25: =IF(I25=1,INDEX('前提と出典'!B80:B83,'前提と出典'!$B$18+1)+G25*INDEX('前提と出典'!C80:C83,'前提と出典'!$B$18+1),0) -> 227.93922 | V25: =IF(I25=1,INDEX('前提と出典'!D80:D83,'前提と出典'!$B$18+1)+G25*INDEX('前提と出典'!E80:E83,'前提と出典'!$B$18+1),0) -> 593.33333 | W25: =L25-Q25 -> 4193.5484 | X25: =N25-R25 -> 1006.4516
A26: 1 | B26: 3 | C26: 1 | D26: ='前提と出典'!D55*(1-'前提と出典'!$B$21) -> 0.06 | E26: =ROUNDUP('前提と出典'!B55*'前提と出典'!$B$23,0) -> 45 | F26: ='前提と出典'!A55 -> 18 | G26: =MAX(1,ROUNDUP(E26*'前提と出典'!$B$25*'前提と出典'!E11,0)) -> 14 | H26: =IF(AND(F26>=1,F26<=100),1,0) -> 1 | I26: =IF(G26<=50,1,0) -> 1 | J26: =H26*I26 -> 1 | K26: =IF(A26='前提と出典'!$B$14,D26,0) -> 0.06 | L26: =IF(H26=0,0,IF(F26<=INDEX('前提と出典'!B41:B43,'前提と出典'!$B$15+1),INDEX('前提と出典'!C41:C43,'前提と出典'!$B$15+1),IF(F26<=INDEX('前提と出典'!D41:D43,'前提と出典'!$B$15+1),INDEX('前提と出典'!E41:E43,'前提と出典'!$B$15+1),INDEX('前提と出典'!G41:G43,'前提と出典'!$B$15+1)))) -> 5000 | M26: =IF(H26=0,0,IF('前提と出典'!$B$33=1,MIN(F26,10)*300+MIN(MAX(0,F26-10),20)*250+MAX(0,F26-30)*200,F26*300)) -> 5000 | N26: =IF(I26=0,0,IF(G26<=INDEX('前提と出典'!B46:B48,'前提と出典'!$B$16+1),INDEX('前提と出典'!C46:C48,'前提と出典'!$B$16+1),IF(G26<=INDEX('前提と出典'!D46:D48,'前提と出典'!$B$16+1),INDEX('前提と出典'!E46:E48,'前提と出典'!$B$16+1),IF(G26<=INDEX('前提と出典'!F46:F48,'前提と出典'!$B$16+1),INDEX('前提と出典'!G46:G48,'前提と出典'!$B$16+1),INDEX('前提と出典'!I46:I48,'前提と出典'!$B$16+1))))) -> 2500 | O26: =IF(I26=1,G26*'前提と出典'!$B$13,0) -> 2800 | P26: =IF(J26=1,MIN('前提と出典'!$B$17,L26+N26),0) -> 1000 | Q26: =IF(J26=0,0,IF('前提と出典'!$B$19=0,P26*L26/(L26+N26),MIN(P26,L26))) -> 666.66667 | R26: =P26-Q26 -> 333.33333 | S26: =IF(H26=1,'前提と出典'!$B$11+F26*'前提と出典'!$B$12,0) -> 68 | T26: =IF(H26=1,('前提と出典'!$B$9+F26*'前提と出典'!$B$10)/60*'前提と出典'!$B$8,0) -> 653.33333 | U26: =IF(I26=1,INDEX('前提と出典'!B80:B83,'前提と出典'!$B$18+1)+G26*INDEX('前提と出典'!C80:C83,'前提と出典'!$B$18+1),0) -> 326.79434 | V26: =IF(I26=1,INDEX('前提と出典'!D80:D83,'前提と出典'!$B$18+1)+G26*INDEX('前提と出典'!E80:E83,'前提と出典'!$B$18+1),0) -> 626.66667 | W26: =L26-Q26 -> 4333.3333 | X26: =N26-R26 -> 2166.6667
A27: 1 | B27: 4 | C27: 0 | D27: ='前提と出典'!D56*'前提と出典'!$B$21 -> 0.021 | E27: =ROUNDUP('前提と出典'!B56*'前提と出典'!$B$22,0) -> 180 | F27: ='前提と出典'!A56 -> 40 | G27: =MAX(1,ROUNDUP(E27*'前提と出典'!$B$24*'前提と出典'!E11,0)) -> 18 | H27: =IF(AND(F27>=1,F27<=100),1,0) -> 1 | I27: =IF(G27<=50,1,0) -> 1 | J27: =H27*I27 -> 1 | K27: =IF(A27='前提と出典'!$B$14,D27,0) -> 0.021 | L27: =IF(H27=0,0,IF(F27<=INDEX('前提と出典'!B41:B43,'前提と出典'!$B$15+1),INDEX('前提と出典'!C41:C43,'前提と出典'!$B$15+1),IF(F27<=INDEX('前提と出典'!D41:D43,'前提と出典'!$B$15+1),INDEX('前提と出典'!E41:E43,'前提と出典'!$B$15+1),INDEX('前提と出典'!G41:G43,'前提と出典'!$B$15+1)))) -> 5000 | M27: =IF(H27=0,0,IF('前提と出典'!$B$33=1,MIN(F27,10)*300+MIN(MAX(0,F27-10),20)*250+MAX(0,F27-30)*200,F27*300)) -> 10000 | N27: =IF(I27=0,0,IF(G27<=INDEX('前提と出典'!B46:B48,'前提と出典'!$B$16+1),INDEX('前提と出典'!C46:C48,'前提と出典'!$B$16+1),IF(G27<=INDEX('前提と出典'!D46:D48,'前提と出典'!$B$16+1),INDEX('前提と出典'!E46:E48,'前提と出典'!$B$16+1),IF(G27<=INDEX('前提と出典'!F46:F48,'前提と出典'!$B$16+1),INDEX('前提と出典'!G46:G48,'前提と出典'!$B$16+1),INDEX('前提と出典'!I46:I48,'前提と出典'!$B$16+1))))) -> 2500 | O27: =IF(I27=1,G27*'前提と出典'!$B$13,0) -> 3600 | P27: =IF(J27=1,MIN('前提と出典'!$B$17,L27+N27),0) -> 1000 | Q27: =IF(J27=0,0,IF('前提と出典'!$B$19=0,P27*L27/(L27+N27),MIN(P27,L27))) -> 666.66667 | R27: =P27-Q27 -> 333.33333 | S27: =IF(H27=1,'前提と出典'!$B$11+F27*'前提と出典'!$B$12,0) -> 90 | T27: =IF(H27=1,('前提と出典'!$B$9+F27*'前提と出典'!$B$10)/60*'前提と出典'!$B$8,0) -> 800 | U27: =IF(I27=1,INDEX('前提と出典'!B80:B83,'前提と出典'!$B$18+1)+G27*INDEX('前提と出典'!C80:C83,'前提と出典'!$B$18+1),0) -> 405.87844 | V27: =IF(I27=1,INDEX('前提と出典'!D80:D83,'前提と出典'!$B$18+1)+G27*INDEX('前提と出典'!E80:E83,'前提と出典'!$B$18+1),0) -> 653.33333 | W27: =L27-Q27 -> 4333.3333 | X27: =N27-R27 -> 2166.6667
A28: 1 | B28: 4 | C28: 1 | D28: ='前提と出典'!D56*(1-'前提と出典'!$B$21) -> 0.009 | E28: =ROUNDUP('前提と出典'!B56*'前提と出典'!$B$23,0) -> 90 | F28: ='前提と出典'!A56 -> 40 | G28: =MAX(1,ROUNDUP(E28*'前提と出典'!$B$25*'前提と出典'!E11,0)) -> 27 | H28: =IF(AND(F28>=1,F28<=100),1,0) -> 1 | I28: =IF(G28<=50,1,0) -> 1 | J28: =H28*I28 -> 1 | K28: =IF(A28='前提と出典'!$B$14,D28,0) -> 0.009 | L28: =IF(H28=0,0,IF(F28<=INDEX('前提と出典'!B41:B43,'前提と出典'!$B$15+1),INDEX('前提と出典'!C41:C43,'前提と出典'!$B$15+1),IF(F28<=INDEX('前提と出典'!D41:D43,'前提と出典'!$B$15+1),INDEX('前提と出典'!E41:E43,'前提と出典'!$B$15+1),INDEX('前提と出典'!G41:G43,'前提と出典'!$B$15+1)))) -> 5000 | M28: =IF(H28=0,0,IF('前提と出典'!$B$33=1,MIN(F28,10)*300+MIN(MAX(0,F28-10),20)*250+MAX(0,F28-30)*200,F28*300)) -> 10000 | N28: =IF(I28=0,0,IF(G28<=INDEX('前提と出典'!B46:B48,'前提と出典'!$B$16+1),INDEX('前提と出典'!C46:C48,'前提と出典'!$B$16+1),IF(G28<=INDEX('前提と出典'!D46:D48,'前提と出典'!$B$16+1),INDEX('前提と出典'!E46:E48,'前提と出典'!$B$16+1),IF(G28<=INDEX('前提と出典'!F46:F48,'前提と出典'!$B$16+1),INDEX('前提と出典'!G46:G48,'前提と出典'!$B$16+1),INDEX('前提と出典'!I46:I48,'前提と出典'!$B$16+1))))) -> 2500 | O28: =IF(I28=1,G28*'前提と出典'!$B$13,0) -> 5400 | P28: =IF(J28=1,MIN('前提と出典'!$B$17,L28+N28),0) -> 1000 | Q28: =IF(J28=0,0,IF('前提と出典'!$B$19=0,P28*L28/(L28+N28),MIN(P28,L28))) -> 666.66667 | R28: =P28-Q28 -> 333.33333 | S28: =IF(H28=1,'前提と出典'!$B$11+F28*'前提と出典'!$B$12,0) -> 90 | T28: =IF(H28=1,('前提と出典'!$B$9+F28*'前提と出典'!$B$10)/60*'前提と出典'!$B$8,0) -> 800 | U28: =IF(I28=1,INDEX('前提と出典'!B80:B83,'前提と出典'!$B$18+1)+G28*INDEX('前提と出典'!C80:C83,'前提と出典'!$B$18+1),0) -> 583.81766 | V28: =IF(I28=1,INDEX('前提と出典'!D80:D83,'前提と出典'!$B$18+1)+G28*INDEX('前提と出典'!E80:E83,'前提と出典'!$B$18+1),0) -> 713.33333 | W28: =L28-Q28 -> 4333.3333 | X28: =N28-R28 -> 2166.6667
A29: 1 | B29: 5 | C29: 0 | D29: ='前提と出典'!D57*'前提と出典'!$B$21 -> 0.0105 | E29: =ROUNDUP('前提と出典'!B57*'前提と出典'!$B$22,0) -> 300 | F29: ='前提と出典'!A57 -> 70 | G29: =MAX(1,ROUNDUP(E29*'前提と出典'!$B$24*'前提と出典'!E11,0)) -> 30 | H29: =IF(AND(F29>=1,F29<=100),1,0) -> 1 | I29: =IF(G29<=50,1,0) -> 1 | J29: =H29*I29 -> 1 | K29: =IF(A29='前提と出典'!$B$14,D29,0) -> 0.0105 | L29: =IF(H29=0,0,IF(F29<=INDEX('前提と出典'!B41:B43,'前提と出典'!$B$15+1),INDEX('前提と出典'!C41:C43,'前提と出典'!$B$15+1),IF(F29<=INDEX('前提と出典'!D41:D43,'前提と出典'!$B$15+1),INDEX('前提と出典'!E41:E43,'前提と出典'!$B$15+1),INDEX('前提と出典'!G41:G43,'前提と出典'!$B$15+1)))) -> 5000 | M29: =IF(H29=0,0,IF('前提と出典'!$B$33=1,MIN(F29,10)*300+MIN(MAX(0,F29-10),20)*250+MAX(0,F29-30)*200,F29*300)) -> 16000 | N29: =IF(I29=0,0,IF(G29<=INDEX('前提と出典'!B46:B48,'前提と出典'!$B$16+1),INDEX('前提と出典'!C46:C48,'前提と出典'!$B$16+1),IF(G29<=INDEX('前提と出典'!D46:D48,'前提と出典'!$B$16+1),INDEX('前提と出典'!E46:E48,'前提と出典'!$B$16+1),IF(G29<=INDEX('前提と出典'!F46:F48,'前提と出典'!$B$16+1),INDEX('前提と出典'!G46:G48,'前提と出典'!$B$16+1),INDEX('前提と出典'!I46:I48,'前提と出典'!$B$16+1))))) -> 2500 | O29: =IF(I29=1,G29*'前提と出典'!$B$13,0) -> 6000 | P29: =IF(J29=1,MIN('前提と出典'!$B$17,L29+N29),0) -> 1000 | Q29: =IF(J29=0,0,IF('前提と出典'!$B$19=0,P29*L29/(L29+N29),MIN(P29,L29))) -> 666.66667 | R29: =P29-Q29 -> 333.33333 | S29: =IF(H29=1,'前提と出典'!$B$11+F29*'前提と出典'!$B$12,0) -> 120 | T29: =IF(H29=1,('前提と出典'!$B$9+F29*'前提と出典'!$B$10)/60*'前提と出典'!$B$8,0) -> 1000 | U29: =IF(I29=1,INDEX('前提と出典'!B80:B83,'前提と出典'!$B$18+1)+G29*INDEX('前提と出典'!C80:C83,'前提と出典'!$B$18+1),0) -> 643.13073 | V29: =IF(I29=1,INDEX('前提と出典'!D80:D83,'前提と出典'!$B$18+1)+G29*INDEX('前提と出典'!E80:E83,'前提と出典'!$B$18+1),0) -> 733.33333 | W29: =L29-Q29 -> 4333.3333 | X29: =N29-R29 -> 2166.6667
A30: 1 | B30: 5 | C30: 1 | D30: ='前提と出典'!D57*(1-'前提と出典'!$B$21) -> 0.0045 | E30: =ROUNDUP('前提と出典'!B57*'前提と出典'!$B$23,0) -> 150 | F30: ='前提と出典'!A57 -> 70 | G30: =MAX(1,ROUNDUP(E30*'前提と出典'!$B$25*'前提と出典'!E11,0)) -> 45 | H30: =IF(AND(F30>=1,F30<=100),1,0) -> 1 | I30: =IF(G30<=50,1,0) -> 1 | J30: =H30*I30 -> 1 | K30: =IF(A30='前提と出典'!$B$14,D30,0) -> 0.0045 | L30: =IF(H30=0,0,IF(F30<=INDEX('前提と出典'!B41:B43,'前提と出典'!$B$15+1),INDEX('前提と出典'!C41:C43,'前提と出典'!$B$15+1),IF(F30<=INDEX('前提と出典'!D41:D43,'前提と出典'!$B$15+1),INDEX('前提と出典'!E41:E43,'前提と出典'!$B$15+1),INDEX('前提と出典'!G41:G43,'前提と出典'!$B$15+1)))) -> 5000 | M30: =IF(H30=0,0,IF('前提と出典'!$B$33=1,MIN(F30,10)*300+MIN(MAX(0,F30-10),20)*250+MAX(0,F30-30)*200,F30*300)) -> 16000 | N30: =IF(I30=0,0,IF(G30<=INDEX('前提と出典'!B46:B48,'前提と出典'!$B$16+1),INDEX('前提と出典'!C46:C48,'前提と出典'!$B$16+1),IF(G30<=INDEX('前提と出典'!D46:D48,'前提と出典'!$B$16+1),INDEX('前提と出典'!E46:E48,'前提と出典'!$B$16+1),IF(G30<=INDEX('前提と出典'!F46:F48,'前提と出典'!$B$16+1),INDEX('前提と出典'!G46:G48,'前提と出典'!$B$16+1),INDEX('前提と出典'!I46:I48,'前提と出典'!$B$16+1))))) -> 2500 | O30: =IF(I30=1,G30*'前提と出典'!$B$13,0) -> 9000 | P30: =IF(J30=1,MIN('前提と出典'!$B$17,L30+N30),0) -> 1000 | Q30: =IF(J30=0,0,IF('前提と出典'!$B$19=0,P30*L30/(L30+N30),MIN(P30,L30))) -> 666.66667 | R30: =P30-Q30 -> 333.33333 | S30: =IF(H30=1,'前提と出典'!$B$11+F30*'前提と出典'!$B$12,0) -> 120 | T30: =IF(H30=1,('前提と出典'!$B$9+F30*'前提と出典'!$B$10)/60*'前提と出典'!$B$8,0) -> 1000 | U30: =IF(I30=1,INDEX('前提と出典'!B80:B83,'前提と出典'!$B$18+1)+G30*INDEX('前提と出典'!C80:C83,'前提と出典'!$B$18+1),0) -> 939.6961 | V30: =IF(I30=1,INDEX('前提と出典'!D80:D83,'前提と出典'!$B$18+1)+G30*INDEX('前提と出典'!E80:E83,'前提と出典'!$B$18+1),0) -> 833.33333 | W30: =L30-Q30 -> 4333.3333 | X30: =N30-R30 -> 2166.6667
A31: 1 | B31: 6 | C31: 0 | D31: ='前提と出典'!D58*'前提と出典'!$B$21 -> 0.0035 | E31: =ROUNDUP('前提と出典'!B58*'前提と出典'!$B$22,0) -> 600 | F31: ='前提と出典'!A58 -> 130 | G31: =MAX(1,ROUNDUP(E31*'前提と出典'!$B$24*'前提と出典'!E11,0)) -> 60 | H31: =IF(AND(F31>=1,F31<=100),1,0) -> 0 | I31: =IF(G31<=50,1,0) -> 0 | J31: =H31*I31 -> 0 | K31: =IF(A31='前提と出典'!$B$14,D31,0) -> 0.0035 | L31: =IF(H31=0,0,IF(F31<=INDEX('前提と出典'!B41:B43,'前提と出典'!$B$15+1),INDEX('前提と出典'!C41:C43,'前提と出典'!$B$15+1),IF(F31<=INDEX('前提と出典'!D41:D43,'前提と出典'!$B$15+1),INDEX('前提と出典'!E41:E43,'前提と出典'!$B$15+1),INDEX('前提と出典'!G41:G43,'前提と出典'!$B$15+1)))) -> 0 | M31: =IF(H31=0,0,IF('前提と出典'!$B$33=1,MIN(F31,10)*300+MIN(MAX(0,F31-10),20)*250+MAX(0,F31-30)*200,F31*300)) -> 0 | N31: =IF(I31=0,0,IF(G31<=INDEX('前提と出典'!B46:B48,'前提と出典'!$B$16+1),INDEX('前提と出典'!C46:C48,'前提と出典'!$B$16+1),IF(G31<=INDEX('前提と出典'!D46:D48,'前提と出典'!$B$16+1),INDEX('前提と出典'!E46:E48,'前提と出典'!$B$16+1),IF(G31<=INDEX('前提と出典'!F46:F48,'前提と出典'!$B$16+1),INDEX('前提と出典'!G46:G48,'前提と出典'!$B$16+1),INDEX('前提と出典'!I46:I48,'前提と出典'!$B$16+1))))) -> 0 | O31: =IF(I31=1,G31*'前提と出典'!$B$13,0) -> 0 | P31: =IF(J31=1,MIN('前提と出典'!$B$17,L31+N31),0) -> 0 | Q31: =IF(J31=0,0,IF('前提と出典'!$B$19=0,P31*L31/(L31+N31),MIN(P31,L31))) -> 0 | R31: =P31-Q31 -> 0 | S31: =IF(H31=1,'前提と出典'!$B$11+F31*'前提と出典'!$B$12,0) -> 0 | T31: =IF(H31=1,('前提と出典'!$B$9+F31*'前提と出典'!$B$10)/60*'前提と出典'!$B$8,0) -> 0 | U31: =IF(I31=1,INDEX('前提と出典'!B80:B83,'前提と出典'!$B$18+1)+G31*INDEX('前提と出典'!C80:C83,'前提と出典'!$B$18+1),0) -> 0 | V31: =IF(I31=1,INDEX('前提と出典'!D80:D83,'前提と出典'!$B$18+1)+G31*INDEX('前提と出典'!E80:E83,'前提と出典'!$B$18+1),0) -> 0 | W31: =L31-Q31 -> 0 | X31: =N31-R31 -> 0
A32: 1 | B32: 6 | C32: 1 | D32: ='前提と出典'!D58*(1-'前提と出典'!$B$21) -> 0.0015 | E32: =ROUNDUP('前提と出典'!B58*'前提と出典'!$B$23,0) -> 300 | F32: ='前提と出典'!A58 -> 130 | G32: =MAX(1,ROUNDUP(E32*'前提と出典'!$B$25*'前提と出典'!E11,0)) -> 90 | H32: =IF(AND(F32>=1,F32<=100),1,0) -> 0 | I32: =IF(G32<=50,1,0) -> 0 | J32: =H32*I32 -> 0 | K32: =IF(A32='前提と出典'!$B$14,D32,0) -> 0.0015 | L32: =IF(H32=0,0,IF(F32<=INDEX('前提と出典'!B41:B43,'前提と出典'!$B$15+1),INDEX('前提と出典'!C41:C43,'前提と出典'!$B$15+1),IF(F32<=INDEX('前提と出典'!D41:D43,'前提と出典'!$B$15+1),INDEX('前提と出典'!E41:E43,'前提と出典'!$B$15+1),INDEX('前提と出典'!G41:G43,'前提と出典'!$B$15+1)))) -> 0 | M32: =IF(H32=0,0,IF('前提と出典'!$B$33=1,MIN(F32,10)*300+MIN(MAX(0,F32-10),20)*250+MAX(0,F32-30)*200,F32*300)) -> 0 | N32: =IF(I32=0,0,IF(G32<=INDEX('前提と出典'!B46:B48,'前提と出典'!$B$16+1),INDEX('前提と出典'!C46:C48,'前提と出典'!$B$16+1),IF(G32<=INDEX('前提と出典'!D46:D48,'前提と出典'!$B$16+1),INDEX('前提と出典'!E46:E48,'前提と出典'!$B$16+1),IF(G32<=INDEX('前提と出典'!F46:F48,'前提と出典'!$B$16+1),INDEX('前提と出典'!G46:G48,'前提と出典'!$B$16+1),INDEX('前提と出典'!I46:I48,'前提と出典'!$B$16+1))))) -> 0 | O32: =IF(I32=1,G32*'前提と出典'!$B$13,0) -> 0 | P32: =IF(J32=1,MIN('前提と出典'!$B$17,L32+N32),0) -> 0 | Q32: =IF(J32=0,0,IF('前提と出典'!$B$19=0,P32*L32/(L32+N32),MIN(P32,L32))) -> 0 | R32: =P32-Q32 -> 0 | S32: =IF(H32=1,'前提と出典'!$B$11+F32*'前提と出典'!$B$12,0) -> 0 | T32: =IF(H32=1,('前提と出典'!$B$9+F32*'前提と出典'!$B$10)/60*'前提と出典'!$B$8,0) -> 0 | U32: =IF(I32=1,INDEX('前提と出典'!B80:B83,'前提と出典'!$B$18+1)+G32*INDEX('前提と出典'!C80:C83,'前提と出典'!$B$18+1),0) -> 0 | V32: =IF(I32=1,INDEX('前提と出典'!D80:D83,'前提と出典'!$B$18+1)+G32*INDEX('前提と出典'!E80:E83,'前提と出典'!$B$18+1),0) -> 0 | W32: =L32-Q32 -> 0 | X32: =N32-R32 -> 0
A33: 2 | B33: 0 | C33: 0 | D33: ='前提と出典'!E52*'前提と出典'!$B$21 -> 0.035 | E33: =ROUNDUP('前提と出典'!B52*'前提と出典'!$B$22,0) -> 6 | F33: ='前提と出典'!A52 -> 0 | G33: =MAX(1,ROUNDUP(E33*'前提と出典'!$B$24*'前提と出典'!E12,0)) -> 1 | H33: =IF(AND(F33>=1,F33<=100),1,0) -> 0 | I33: =IF(G33<=50,1,0) -> 1 | J33: =H33*I33 -> 0 | K33: =IF(A33='前提と出典'!$B$14,D33,0) -> 0 | L33: =IF(H33=0,0,IF(F33<=INDEX('前提と出典'!B41:B43,'前提と出典'!$B$15+1),INDEX('前提と出典'!C41:C43,'前提と出典'!$B$15+1),IF(F33<=INDEX('前提と出典'!D41:D43,'前提と出典'!$B$15+1),INDEX('前提と出典'!E41:E43,'前提と出典'!$B$15+1),INDEX('前提と出典'!G41:G43,'前提と出典'!$B$15+1)))) -> 0 | M33: =IF(H33=0,0,IF('前提と出典'!$B$33=1,MIN(F33,10)*300+MIN(MAX(0,F33-10),20)*250+MAX(0,F33-30)*200,F33*300)) -> 0 | N33: =IF(I33=0,0,IF(G33<=INDEX('前提と出典'!B46:B48,'前提と出典'!$B$16+1),INDEX('前提と出典'!C46:C48,'前提と出典'!$B$16+1),IF(G33<=INDEX('前提と出典'!D46:D48,'前提と出典'!$B$16+1),INDEX('前提と出典'!E46:E48,'前提と出典'!$B$16+1),IF(G33<=INDEX('前提と出典'!F46:F48,'前提と出典'!$B$16+1),INDEX('前提と出典'!G46:G48,'前提と出典'!$B$16+1),INDEX('前提と出典'!I46:I48,'前提と出典'!$B$16+1))))) -> 1200 | O33: =IF(I33=1,G33*'前提と出典'!$B$13,0) -> 200 | P33: =IF(J33=1,MIN('前提と出典'!$B$17,L33+N33),0) -> 0 | Q33: =IF(J33=0,0,IF('前提と出典'!$B$19=0,P33*L33/(L33+N33),MIN(P33,L33))) -> 0 | R33: =P33-Q33 -> 0 | S33: =IF(H33=1,'前提と出典'!$B$11+F33*'前提と出典'!$B$12,0) -> 0 | T33: =IF(H33=1,('前提と出典'!$B$9+F33*'前提と出典'!$B$10)/60*'前提と出典'!$B$8,0) -> 0 | U33: =IF(I33=1,INDEX('前提と出典'!B80:B83,'前提と出典'!$B$18+1)+G33*INDEX('前提と出典'!C80:C83,'前提と出典'!$B$18+1),0) -> 69.771024 | V33: =IF(I33=1,INDEX('前提と出典'!D80:D83,'前提と出典'!$B$18+1)+G33*INDEX('前提と出典'!E80:E83,'前提と出典'!$B$18+1),0) -> 540 | W33: =L33-Q33 -> 0 | X33: =N33-R33 -> 1200
A34: 2 | B34: 0 | C34: 1 | D34: ='前提と出典'!E52*(1-'前提と出典'!$B$21) -> 0.015 | E34: =ROUNDUP('前提と出典'!B52*'前提と出典'!$B$23,0) -> 3 | F34: ='前提と出典'!A52 -> 0 | G34: =MAX(1,ROUNDUP(E34*'前提と出典'!$B$25*'前提と出典'!E12,0)) -> 2 | H34: =IF(AND(F34>=1,F34<=100),1,0) -> 0 | I34: =IF(G34<=50,1,0) -> 1 | J34: =H34*I34 -> 0 | K34: =IF(A34='前提と出典'!$B$14,D34,0) -> 0 | L34: =IF(H34=0,0,IF(F34<=INDEX('前提と出典'!B41:B43,'前提と出典'!$B$15+1),INDEX('前提と出典'!C41:C43,'前提と出典'!$B$15+1),IF(F34<=INDEX('前提と出典'!D41:D43,'前提と出典'!$B$15+1),INDEX('前提と出典'!E41:E43,'前提と出典'!$B$15+1),INDEX('前提と出典'!G41:G43,'前提と出典'!$B$15+1)))) -> 0 | M34: =IF(H34=0,0,IF('前提と出典'!$B$33=1,MIN(F34,10)*300+MIN(MAX(0,F34-10),20)*250+MAX(0,F34-30)*200,F34*300)) -> 0 | N34: =IF(I34=0,0,IF(G34<=INDEX('前提と出典'!B46:B48,'前提と出典'!$B$16+1),INDEX('前提と出典'!C46:C48,'前提と出典'!$B$16+1),IF(G34<=INDEX('前提と出典'!D46:D48,'前提と出典'!$B$16+1),INDEX('前提と出典'!E46:E48,'前提と出典'!$B$16+1),IF(G34<=INDEX('前提と出典'!F46:F48,'前提と出典'!$B$16+1),INDEX('前提と出典'!G46:G48,'前提と出典'!$B$16+1),INDEX('前提と出典'!I46:I48,'前提と出典'!$B$16+1))))) -> 1200 | O34: =IF(I34=1,G34*'前提と出典'!$B$13,0) -> 400 | P34: =IF(J34=1,MIN('前提と出典'!$B$17,L34+N34),0) -> 0 | Q34: =IF(J34=0,0,IF('前提と出典'!$B$19=0,P34*L34/(L34+N34),MIN(P34,L34))) -> 0 | R34: =P34-Q34 -> 0 | S34: =IF(H34=1,'前提と出典'!$B$11+F34*'前提と出典'!$B$12,0) -> 0 | T34: =IF(H34=1,('前提と出典'!$B$9+F34*'前提と出典'!$B$10)/60*'前提と出典'!$B$8,0) -> 0 | U34: =IF(I34=1,INDEX('前提と出典'!B80:B83,'前提と出典'!$B$18+1)+G34*INDEX('前提と出典'!C80:C83,'前提と出典'!$B$18+1),0) -> 89.542049 | V34: =IF(I34=1,INDEX('前提と出典'!D80:D83,'前提と出典'!$B$18+1)+G34*INDEX('前提と出典'!E80:E83,'前提と出典'!$B$18+1),0) -> 546.66667 | W34: =L34-Q34 -> 0 | X34: =N34-R34 -> 1200
